Workbook

Sheet Motor_Car
A1: Motor Car (private)
A2: Registrations (numbers) by fuel group. Formulas pull from Raw_Fuel_Detail using the fuel-group row.
A4: Financial Year | B4: EV | C4: Hybrid | D4: Petrol | E4: Diesel | F4: CNG | G4: LPG | H4: Other / NA | I4: Total | J4: EV % | K4: Hybrid % | L4: Petrol % | M4: Diesel % | N4: CNG %
A5: FY04-05 | B5: =SUMPRODUCT((Raw_Fuel_Detail!$A$3:$A$44=$A5)*(Raw_Fuel_Detail!$B$3:$B$44="Motor Car")*(Raw_Fuel_Detail!$C$1:$AL$1=B$4)*Raw_Fuel_Detail!$C$3:$AL$44) -> 203 | C5: =SUMPRODUCT((Raw_Fuel_Detail!$A$3:$A$44=$A5)*(Raw_Fuel_Detail!$B$3:$B$44="Motor Car")*(Raw_Fuel_Detail!$C$1:$AL$1=C$4)*Raw_Fuel_Detail!$C$3:$AL$44) -> 23 | D5: =SUMPRODUCT((Raw_Fuel_Detail!$A$3:$A$44=$A5)*(Raw_Fuel_Detail!$B$3:$B$44="Motor Car")*(Raw_Fuel_Detail!$C$1:$AL$1=D$4)*Raw_Fuel_Detail!$C$3:$AL$44) -> 543547 | E5: =SUMPRODUCT((Raw_Fuel_Detail!$A$3:$A$44=$A5)*(Raw_Fuel_Detail!$B$3:$B$44="Motor Car")*(Raw_Fuel_Detail!$C$1:$AL$1=E$4)*Raw_Fuel_Detail!$C$3:$AL$44) -> 247776 | F5: =SUMPRODUCT((Raw_Fuel_Detail!$A$3:$A$44=$A5)*(Raw_Fuel_Detail!$B$3:$B$44="Motor Car")*(Raw_Fuel_Detail!$C$1:$AL$1=F$4)*Raw_Fuel_Detail!$C$3:$AL$44) -> 54883 | G5: =SUMPRODUCT((Raw_Fuel_Detail!$A$3:$A$44=$A5)*(Raw_Fuel_Detail!$B$3:$B$44="Motor Car")*(Raw_Fuel_Detail!$C$1:$AL$1=G$4)*Raw_Fuel_Detail!$C$3:$AL$44) -> 47858 | H5: =SUMPRODUCT((Raw_Fuel_Detail!$A$3:$A$44=$A5)*(Raw_Fuel_Detail!$B$3:$B$44="Motor Car")*(Raw_Fuel_Detail!$C$1:$AL$1=H$4)*Raw_Fuel_Detail!$C$3:$AL$44) -> 1890 | I5: =SUM(B5:H5) -> 896180 | J5: =IF($I5=0,0,B5/$I5) -> 0.00022651699 | K5: =IF($I5=0,0,C5/$I5) -> 2.5664487e-05 | L5: =IF($I5=0,0,D5/$I5) -> 0.60651543 | M5: =IF($I5=0,0,E5/$I5) -> 0.27648017 | N5: =IF($I5=0,0,F5/$I5) -> 0.061241045
A6: FY05-06 | B6: =SUMPRODUCT((Raw_Fuel_Detail!$A$3:$A$44=$A6)*(Raw_Fuel_Detail!$B$3:$B$44="Motor Car")*(Raw_Fuel_Detail!$C$1:$AL$1=B$4)*Raw_Fuel_Detail!$C$3:$AL$44) -> 180 | C6: =SUMPRODUCT((Raw_Fuel_Detail!$A$3:$A$44=$A6)*(Raw_Fuel_Detail!$B$3:$B$44="Motor Car")*(Raw_Fuel_Detail!$C$1:$AL$1=C$4)*Raw_Fuel_Detail!$C$3:$AL$44) -> 19 | D6: =SUMPRODUCT((Raw_Fuel_Detail!$A$3:$A$44=$A6)*(Raw_Fuel_Detail!$B$3:$B$44="Motor Car")*(Raw_Fuel_Detail!$C$1:$AL$1=D$4)*Raw_Fuel_Detail!$C$3:$AL$44) -> 606600 | E6: =SUMPRODUCT((Raw_Fuel_Detail!$A$3:$A$44=$A6)*(Raw_Fuel_Detail!$B$3:$B$44="Motor Car")*(Raw_Fuel_Detail!$C$1:$AL$1=E$4)*Raw_Fuel_Detail!$C$3:$AL$44) -> 279128 | F6: =SUMPRODUCT((Raw_Fuel_Detail!$A$3:$A$44=$A6)*(Raw_Fuel_Detail!$B$3:$B$44="Motor Car")*(Raw_Fuel_Detail!$C$1:$AL$1=F$4)*Raw_Fuel_Detail!$C$3:$AL$44) -> 70494 | G6: =SUMPRODUCT((Raw_Fuel_Detail!$A$3:$A$44=$A6)*(Raw_Fuel_Detail!$B$3:$B$44="Motor Car")*(Raw_Fuel_Detail!$C$1:$AL$1=G$4)*Raw_Fuel_Detail!$C$3:$AL$44) -> 49220 | H6: =SUMPRODUCT((Raw_Fuel_Detail!$A$3:$A$44=$A6)*(Raw_Fuel_Detail!$B$3:$B$44="Motor Car")*(Raw_Fuel_Detail!$C$1:$AL$1=H$4)*Raw_Fuel_Detail!$C$3:$AL$44) -> 1938 | I6: =SUM(B6:H6) -> 1007579 | J6: =IF($I6=0,0,B6/$I6) -> 0.00017864604 | K6: =IF($I6=0,0,C6/$I6) -> 1.8857082e-05 | L6: =IF($I6=0,0,D6/$I6) -> 0.60203716 | M6: =IF($I6=0,0,E6/$I6) -> 0.2770284 | N6: =IF($I6=0,0,F6/$I6) -> 0.069963745
A7: FY06-07 | B7: =SUMPRODUCT((Raw_Fuel_Detail!$A$3:$A$44=$A7)*(Raw_Fuel_Detail!$B$3:$B$44="Motor Car")*(Raw_Fuel_Detail!$C$1:$AL$1=B$4)*Raw_Fuel_Detail!$C$3:$AL$44) -> 243 | C7: =SUMPRODUCT((Raw_Fuel_Detail!$A$3:$A$44=$A7)*(Raw_Fuel_Detail!$B$3:$B$44="Motor Car")*(Raw_Fuel_Detail!$C$1:$AL$1=C$4)*Raw_Fuel_Detail!$C$3:$AL$44) -> 24 | D7: =SUMPRODUCT((Raw_Fuel_Detail!$A$3:$A$44=$A7)*(Raw_Fuel_Detail!$B$3:$B$44="Motor Car")*(Raw_Fuel_Detail!$C$1:$AL$1=D$4)*Raw_Fuel_Detail!$C$3:$AL$44) -> 711428 | E7: =SUMPRODUCT((Raw_Fuel_Detail!$A$3:$A$44=$A7)*(Raw_Fuel_Detail!$B$3:$B$44="Motor Car")*(Raw_Fuel_Detail!$C$1:$AL$1=E$4)*Raw_Fuel_Detail!$C$3:$AL$44) -> 332590 | F7: =SUMPRODUCT((Raw_Fuel_Detail!$A$3:$A$44=$A7)*(Raw_Fuel_Detail!$B$3:$B$44="Motor Car")*(Raw_Fuel_Detail!$C$1:$AL$1=F$4)*Raw_Fuel_Detail!$C$3:$AL$44) -> 87186 | G7: =SUMPRODUCT((Raw_Fuel_Detail!$A$3:$A$44=$A7)*(Raw_Fuel_Detail!$B$3:$B$44="Motor Car")*(Raw_Fuel_Detail!$C$1:$AL$1=G$4)*Raw_Fuel_Detail!$C$3:$AL$44) -> 71485 | H7: =SUMPRODUCT((Raw_Fuel_Detail!$A$3:$A$44=$A7)*(Raw_Fuel_Detail!$B$3:$B$44="Motor Car")*(Raw_Fuel_Detail!$C$1:$AL$1=H$4)*Raw_Fuel_Detail!$C$3:$AL$44) -> 3201 | I7: =SUM(B7:H7) -> 1206157 | J7: =IF($I7=0,0,B7/$I7) -> 0.00020146631 | K7: =IF($I7=0,0,C7/$I7) -> 1.9897907e-05 | L7: =IF($I7=0,0,D7/$I7) -> 0.58983035 | M7: =IF($I7=0,0,E7/$I7) -> 0.27574354 | N7: =IF($I7=0,0,F7/$I7) -> 0.072284122
A8: FY07-08 | B8: =SUMPRODUCT((Raw_Fuel_Detail!$A$3:$A$44=$A8)*(Raw_Fuel_Detail!$B$3:$B$44="Motor Car")*(Raw_Fuel_Detail!$C$1:$AL$1=B$4)*Raw_Fuel_Detail!$C$3:$AL$44) -> 336 | C8: =SUMPRODUCT((Raw_Fuel_Detail!$A$3:$A$44=$A8)*(Raw_Fuel_Detail!$B$3:$B$44="Motor Car")*(Raw_Fuel_Detail!$C$1:$AL$1=C$4)*Raw_Fuel_Detail!$C$3:$AL$44) -> 20 | D8: =SUMPRODUCT((Raw_Fuel_Detail!$A$3:$A$44=$A8)*(Raw_Fuel_Detail!$B$3:$B$44="Motor Car")*(Raw_Fuel_Detail!$C$1:$AL$1=D$4)*Raw_Fuel_Detail!$C$3:$AL$44) -> 781588 | E8: =SUMPRODUCT((Raw_Fuel_Detail!$A$3:$A$44=$A8)*(Raw_Fuel_Detail!$B$3:$B$44="Motor Car")*(Raw_Fuel_Detail!$C$1:$AL$1=E$4)*Raw_Fuel_Detail!$C$3:$AL$44) -> 417877 | F8: =SUMPRODUCT((Raw_Fuel_Detail!$A$3:$A$44=$A8)*(Raw_Fuel_Detail!$B$3:$B$44="Motor Car")*(Raw_Fuel_Detail!$C$1:$AL$1=F$4)*Raw_Fuel_Detail!$C$3:$AL$44) -> 103114 | G8: =SUMPRODUCT((Raw_Fuel_Detail!$A$3:$A$44=$A8)*(Raw_Fuel_Detail!$B$3:$B$44="Motor Car")*(Raw_Fuel_Detail!$C$1:$AL$1=G$4)*Raw_Fuel_Detail!$C$3:$AL$44) -> 83047 | H8: =SUMPRODUCT((Raw_Fuel_Detail!$A$3:$A$44=$A8)*(Raw_Fuel_Detail!$B$3:$B$44="Motor Car")*(Raw_Fuel_Detail!$C$1:$AL$1=H$4)*Raw_Fuel_Detail!$C$3:$AL$44) -> 2830 | I8: =SUM(B8:H8) -> 1388812 | J8: =IF($I8=0,0,B8/$I8) -> 0.00024193339 | K8: =IF($I8=0,0,C8/$I8) -> 1.4400797e-05 | L8: =IF($I8=0,0,D8/$I8) -> 0.56277452 | M8: =IF($I8=0,0,E8/$I8) -> 0.3008881 | N8: =IF($I8=0,0,F8/$I8) -> 0.07424619
A9: FY08-09 | B9: =SUMPRODUCT((Raw_Fuel_Detail!$A$3:$A$44=$A9)*(Raw_Fuel_Detail!$B$3:$B$44="Motor Car")*(Raw_Fuel_Detail!$C$1:$AL$1=B$4)*Raw_Fuel_Detail!$C$3:$AL$44) -> 490 | C9: =SUMPRODUCT((Raw_Fuel_Detail!$A$3:$A$44=$A9)*(Raw_Fuel_Detail!$B$3:$B$44="Motor Car")*(Raw_Fuel_Detail!$C$1:$AL$1=C$4)*Raw_Fuel_Detail!$C$3:$AL$44) -> 22 | D9: =SUMPRODUCT((Raw_Fuel_Detail!$A$3:$A$44=$A9)*(Raw_Fuel_Detail!$B$3:$B$44="Motor Car")*(Raw_Fuel_Detail!$C$1:$AL$1=D$4)*Raw_Fuel_Detail!$C$3:$AL$44) -> 787685 | E9: =SUMPRODUCT((Raw_Fuel_Detail!$A$3:$A$44=$A9)*(Raw_Fuel_Detail!$B$3:$B$44="Motor Car")*(Raw_Fuel_Detail!$C$1:$AL$1=E$4)*Raw_Fuel_Detail!$C$3:$AL$44) -> 485194 | F9: =SUMPRODUCT((Raw_Fuel_Detail!$A$3:$A$44=$A9)*(Raw_Fuel_Detail!$B$3:$B$44="Motor Car")*(Raw_Fuel_Detail!$C$1:$AL$1=F$4)*Raw_Fuel_Detail!$C$3:$AL$44) -> 101337 | G9: =SUMPRODUCT((Raw_Fuel_Detail!$A$3:$A$44=$A9)*(Raw_Fuel_Detail!$B$3:$B$44="Motor Car")*(Raw_Fuel_Detail!$C$1:$AL$1=G$4)*Raw_Fuel_Detail!$C$3:$AL$44) -> 81774 | H9: =SUMPRODUCT((Raw_Fuel_Detail!$A$3:$A$44=$A9)*(Raw_Fuel_Detail!$B$3:$B$44="Motor Car")*(Raw_Fuel_Detail!$C$1:$AL$1=H$4)*Raw_Fuel_Detail!$C$3:$AL$44) -> 2376 | I9: =SUM(B9:H9) -> 1458878 | J9: =IF($I9=0,0,B9/$I9) -> 0.00033587456 | K9: =IF($I9=0,0,C9/$I9) -> 1.5080082e-05 | L9: =IF($I9=0,0,D9/$I9) -> 0.5399252 | M9: =IF($I9=0,0,E9/$I9) -> 0.33258024 | N9: =IF($I9=0,0,F9/$I9) -> 0.069462285
A10: FY09-10 | B10: =SUMPRODUCT((Raw_Fuel_Detail!$A$3:$A$44=$A10)*(Raw_Fuel_Detail!$B$3:$B$44="Motor Car")*(Raw_Fuel_Detail!$C$1:$AL$1=B$4)*Raw_Fuel_Detail!$C$3:$AL$44) -> 267 | C10: =SUMPRODUCT((Raw_Fuel_Detail!$A$3:$A$44=$A10)*(Raw_Fuel_Detail!$B$3:$B$44="Motor Car")*(Raw_Fuel_Detail!$C$1:$AL$1=C$4)*Raw_Fuel_Detail!$C$3:$AL$44) -> 37 | D10: =SUMPRODUCT((Raw_Fuel_Detail!$A$3:$A$44=$A10)*(Raw_Fuel_Detail!$B$3:$B$44="Motor Car")*(Raw_Fuel_Detail!$C$1:$AL$1=D$4)*Raw_Fuel_Detail!$C$3:$AL$44) -> 977493 | E10: =SUMPRODUCT((Raw_Fuel_Detail!$A$3:$A$44=$A10)*(Raw_Fuel_Detail!$B$3:$B$44="Motor Car")*(Raw_Fuel_Detail!$C$1:$AL$1=E$4)*Raw_Fuel_Detail!$C$3:$AL$44) -> 608490 | F10: =SUMPRODUCT((Raw_Fuel_Detail!$A$3:$A$44=$A10)*(Raw_Fuel_Detail!$B$3:$B$44="Motor Car")*(Raw_Fuel_Detail!$C$1:$AL$1=F$4)*Raw_Fuel_Detail!$C$3:$AL$44) -> 123252 | G10: =SUMPRODUCT((Raw_Fuel_Detail!$A$3:$A$44=$A10)*(Raw_Fuel_Detail!$B$3:$B$44="Motor Car")*(Raw_Fuel_Detail!$C$1:$AL$1=G$4)*Raw_Fuel_Detail!$C$3:$AL$44) -> 94603 | H10: =SUMPRODUCT((Raw_Fuel_Detail!$A$3:$A$44=$A10)*(Raw_Fuel_Detail!$B$3:$B$44="Motor Car")*(Raw_Fuel_Detail!$C$1:$AL$1=H$4)*Raw_Fuel_Detail!$C$3:$AL$44) -> 2471 | I10: =SUM(B10:H10) -> 1806613 | J10: =IF($I10=0,0,B10/$I10) -> 0.00014779037 | K10: =IF($I10=0,0,C10/$I10) -> 2.0480313e-05 | L10: =IF($I10=0,0,D10/$I10) -> 0.54106386 | M10: =IF($I10=0,0,E10/$I10) -> 0.33681259 | N10: =IF($I10=0,0,F10/$I10) -> 0.068222691
A11: FY10-11 | B11: =SUMPRODUCT((Raw_Fuel_Detail!$A$3:$A$44=$A11)*(Raw_Fuel_Detail!$B$3:$B$44="Motor Car")*(Raw_Fuel_Detail!$C$1:$AL$1=B$4)*Raw_Fuel_Detail!$C$3:$AL$44) -> 371 | C11: =SUMPRODUCT((Raw_Fuel_Detail!$A$3:$A$44=$A11)*(Raw_Fuel_Detail!$B$3:$B$44="Motor Car")*(Raw_Fuel_Detail!$C$1:$AL$1=C$4)*Raw_Fuel_Detail!$C$3:$AL$44) -> 26 | D11: =SUMPRODUCT((Raw_Fuel_Detail!$A$3:$A$44=$A11)*(Raw_Fuel_Detail!$B$3:$B$44="Motor Car")*(Raw_Fuel_Detail!$C$1:$AL$1=D$4)*Raw_Fuel_Detail!$C$3:$AL$44) -> 1198165 | E11: =SUMPRODUCT((Raw_Fuel_Detail!$A$3:$A$44=$A11)*(Raw_Fuel_Detail!$B$3:$B$44="Motor Car")*(Raw_Fuel_Detail!$C$1:$AL$1=E$4)*Raw_Fuel_Detail!$C$3:$AL$44) -> 768682 | F11: =SUMPRODUCT((Raw_Fuel_Detail!$A$3:$A$44=$A11)*(Raw_Fuel_Detail!$B$3:$B$44="Motor Car")*(Raw_Fuel_Detail!$C$1:$AL$1=F$4)*Raw_Fuel_Detail!$C$3:$AL$44) -> 168766 | G11: =SUMPRODUCT((Raw_Fuel_Detail!$A$3:$A$44=$A11)*(Raw_Fuel_Detail!$B$3:$B$44="Motor Car")*(Raw_Fuel_Detail!$C$1:$AL$1=G$4)*Raw_Fuel_Detail!$C$3:$AL$44) -> 82160 | H11: =SUMPRODUCT((Raw_Fuel_Detail!$A$3:$A$44=$A11)*(Raw_Fuel_Detail!$B$3:$B$44="Motor Car")*(Raw_Fuel_Detail!$C$1:$AL$1=H$4)*Raw_Fuel_Detail!$C$3:$AL$44) -> 2654 | I11: =SUM(B11:H11) -> 2220824 | J11: =IF($I11=0,0,B11/$I11) -> 0.00016705511 | K11: =IF($I11=0,0,C11/$I11) -> 1.1707366e-05 | L11: =IF($I11=0,0,D11/$I11) -> 0.53951371 | M11: =IF($I11=0,0,E11/$I11) -> 0.34612468 | N11: =IF($I11=0,0,F11/$I11) -> 0.075992514
A12: FY11-12 | B12: =SUMPRODUCT((Raw_Fuel_Detail!$A$3:$A$44=$A12)*(Raw_Fuel_Detail!$B$3:$B$44="Motor Car")*(Raw_Fuel_Detail!$C$1:$AL$1=B$4)*Raw_Fuel_Detail!$C$3:$AL$44) -> 676 | C12: =SUMPRODUCT((Raw_Fuel_Detail!$A$3:$A$44=$A12)*(Raw_Fuel_Detail!$B$3:$B$44="Motor Car")*(Raw_Fuel_Detail!$C$1:$AL$1=C$4)*Raw_Fuel_Detail!$C$3:$AL$44) -> 21 | D12: =SUMPRODUCT((Raw_Fuel_Detail!$A$3:$A$44=$A12)*(Raw_Fuel_Detail!$B$3:$B$44="Motor Car")*(Raw_Fuel_Detail!$C$1:$AL$1=D$4)*Raw_Fuel_Detail!$C$3:$AL$44) -> 1111992 | E12: =SUMPRODUCT((Raw_Fuel_Detail!$A$3:$A$44=$A12)*(Raw_Fuel_Detail!$B$3:$B$44="Motor Car")*(Raw_Fuel_Detail!$C$1:$AL$1=E$4)*Raw_Fuel_Detail!$C$3:$AL$44) -> 1049355 | F12: =SUMPRODUCT((Raw_Fuel_Detail!$A$3:$A$44=$A12)*(Raw_Fuel_Detail!$B$3:$B$44="Motor Car")*(Raw_Fuel_Detail!$C$1:$AL$1=F$4)*Raw_Fuel_Detail!$C$3:$AL$44) -> 182917 | G12: =SUMPRODUCT((Raw_Fuel_Detail!$A$3:$A$44=$A12)*(Raw_Fuel_Detail!$B$3:$B$44="Motor Car")*(Raw_Fuel_Detail!$C$1:$AL$1=G$4)*Raw_Fuel_Detail!$C$3:$AL$44) -> 84023 | H12: =SUMPRODUCT((Raw_Fuel_Detail!$A$3:$A$44=$A12)*(Raw_Fuel_Detail!$B$3:$B$44="Motor Car")*(Raw_Fuel_Detail!$C$1:$AL$1=H$4)*Raw_Fuel_Detail!$C$3:$AL$44) -> 2710 | I12: =SUM(B12:H12) -> 2431694 | J12: =IF($I12=0,0,B12/$I12) -> 0.0002779955 | K12: =IF($I12=0,0,C12/$I12) -> 8.635955e-06 | L12: =IF($I12=0,0,D12/$I12) -> 0.45729109 | M12: =IF($I12=0,0,E12/$I12) -> 0.4315325 | N12: =IF($I12=0,0,F12/$I12) -> 0.075222047
A13: FY12-13 | B13: =SUMPRODUCT((Raw_Fuel_Detail!$A$3:$A$44=$A13)*(Raw_Fuel_Detail!$B$3:$B$44="Motor Car")*(Raw_Fuel_Detail!$C$1:$AL$1=B$4)*Raw_Fuel_Detail!$C$3:$AL$44) -> 208 | C13: =SUMPRODUCT((Raw_Fuel_Detail!$A$3:$A$44=$A13)*(Raw_Fuel_Detail!$B$3:$B$44="Motor Car")*(Raw_Fuel_Detail!$C$1:$AL$1=C$4)*Raw_Fuel_Detail!$C$3:$AL$44) -> 38 | D13: =SUMPRODUCT((Raw_Fuel_Detail!$A$3:$A$44=$A13)*(Raw_Fuel_Detail!$B$3:$B$44="Motor Car")*(Raw_Fuel_Detail!$C$1:$AL$1=D$4)*Raw_Fuel_Detail!$C$3:$AL$44) -> 935337 | E13: =SUMPRODUCT((Raw_Fuel_Detail!$A$3:$A$44=$A13)*(Raw_Fuel_Detail!$B$3:$B$44="Motor Car")*(Raw_Fuel_Detail!$C$1:$AL$1=E$4)*Raw_Fuel_Detail!$C$3:$AL$44) -> 1310734 | F13: =SUMPRODUCT((Raw_Fuel_Detail!$A$3:$A$44=$A13)*(Raw_Fuel_Detail!$B$3:$B$44="Motor Car")*(Raw_Fuel_Detail!$C$1:$AL$1=F$4)*Raw_Fuel_Detail!$C$3:$AL$44) -> 150385 | G13: =SUMPRODUCT((Raw_Fuel_Detail!$A$3:$A$44=$A13)*(Raw_Fuel_Detail!$B$3:$B$44="Motor Car")*(Raw_Fuel_Detail!$C$1:$AL$1=G$4)*Raw_Fuel_Detail!$C$3:$AL$44) -> 63975 | H13: =SUMPRODUCT((Raw_Fuel_Detail!$A$3:$A$44=$A13)*(Raw_Fuel_Detail!$B$3:$B$44="Motor Car")*(Raw_Fuel_Detail!$C$1:$AL$1=H$4)*Raw_Fuel_Detail!$C$3:$AL$44) -> 2430 | I13: =SUM(B13:H13) -> 2463107 | J13: =IF($I13=0,0,B13/$I13) -> 8.4446189e-05 | K13: =IF($I13=0,0,C13/$I13) -> 1.5427669e-05 | L13: =IF($I13=0,0,D13/$I13) -> 0.37973868 | M13: =IF($I13=0,0,E13/$I13) -> 0.53214659 | N13: =IF($I13=0,0,F13/$I13) -> 0.061055001
A14: FY13-14 | B14: =SUMPRODUCT((Raw_Fuel_Detail!$A$3:$A$44=$A14)*(Raw_Fuel_Detail!$B$3:$B$44="Motor Car")*(Raw_Fuel_Detail!$C$1:$AL$1=B$4)*Raw_Fuel_Detail!$C$3:$AL$44) -> 424 | C14: =SUMPRODUCT((Raw_Fuel_Detail!$A$3:$A$44=$A14)*(Raw_Fuel_Detail!$B$3:$B$44="Motor Car")*(Raw_Fuel_Detail!$C$1:$AL$1=C$4)*Raw_Fuel_Detail!$C$3:$AL$44) -> 23 | D14: =SUMPRODUCT((Raw_Fuel_Detail!$A$3:$A$44=$A14)*(Raw_Fuel_Detail!$B$3:$B$44="Motor Car")*(Raw_Fuel_Detail!$C$1:$AL$1=D$4)*Raw_Fuel_Detail!$C$3:$AL$44) -> 959118 | E14: =SUMPRODUCT((Raw_Fuel_Detail!$A$3:$A$44=$A14)*(Raw_Fuel_Detail!$B$3:$B$44="Motor Car")*(Raw_Fuel_Detail!$C$1:$AL$1=E$4)*Raw_Fuel_Detail!$C$3:$AL$44) -> 1211564 | F14: =SUMPRODUCT((Raw_Fuel_Detail!$A$3:$A$44=$A14)*(Raw_Fuel_Detail!$B$3:$B$44="Motor Car")*(Raw_Fuel_Detail!$C$1:$AL$1=F$4)*Raw_Fuel_Detail!$C$3:$AL$44) -> 134424 | G14: =SUMPRODUCT((Raw_Fuel_Detail!$A$3:$A$44=$A14)*(Raw_Fuel_Detail!$B$3:$B$44="Motor Car")*(Raw_Fuel_Detail!$C$1:$AL$1=G$4)*Raw_Fuel_Detail!$C$3:$AL$44) -> 37023 | H14: =SUMPRODUCT((Raw_Fuel_Detail!$A$3:$A$44=$A14)*(Raw_Fuel_Detail!$B$3:$B$44="Motor Car")*(Raw_Fuel_Detail!$C$1:$AL$1=H$4)*Raw_Fuel_Detail!$C$3:$AL$44) -> 1829 | I14: =SUM(B14:H14) -> 2344405 | J14: =IF($I14=0,0,B14/$I14) -> 0.00018085612 | K14: =IF($I14=0,0,C14/$I14) -> 9.8105916e-06 | L14: =IF($I14=0,0,D14/$I14) -> 0.40910935 | M14: =IF($I14=0,0,E14/$I14) -> 0.51678955 | N14: =IF($I14=0,0,F14/$I14) -> 0.057338216
A15: FY14-15 | B15: =SUMPRODUCT((Raw_Fuel_Detail!$A$3:$A$44=$A15)*(Raw_Fuel_Detail!$B$3:$B$44="Motor Car")*(Raw_Fuel_Detail!$C$1:$AL$1=B$4)*Raw_Fuel_Detail!$C$3:$AL$44) -> 574 | C15: =SUMPRODUCT((Raw_Fuel_Detail!$A$3:$A$44=$A15)*(Raw_Fuel_Detail!$B$3:$B$44="Motor Car")*(Raw_Fuel_Detail!$C$1:$AL$1=C$4)*Raw_Fuel_Detail!$C$3:$AL$44) -> 21 | D15: =SUMPRODUCT((Raw_Fuel_Detail!$A$3:$A$44=$A15)*(Raw_Fuel_Detail!$B$3:$B$44="Motor Car")*(Raw_Fuel_Detail!$C$1:$AL$1=D$4)*Raw_Fuel_Detail!$C$3:$AL$44) -> 1125373 | E15: =SUMPRODUCT((Raw_Fuel_Detail!$A$3:$A$44=$A15)*(Raw_Fuel_Detail!$B$3:$B$44="Motor Car")*(Raw_Fuel_Detail!$C$1:$AL$1=E$4)*Raw_Fuel_Detail!$C$3:$AL$44) -> 1178102 | F15: =SUMPRODUCT((Raw_Fuel_Detail!$A$3:$A$44=$A15)*(Raw_Fuel_Detail!$B$3:$B$44="Motor Car")*(Raw_Fuel_Detail!$C$1:$AL$1=F$4)*Raw_Fuel_Detail!$C$3:$AL$44) -> 161107 | G15: =SUMPRODUCT((Raw_Fuel_Detail!$A$3:$A$44=$A15)*(Raw_Fuel_Detail!$B$3:$B$44="Motor Car")*(Raw_Fuel_Detail!$C$1:$AL$1=G$4)*Raw_Fuel_Detail!$C$3:$AL$44) -> 38973 | H15: =SUMPRODUCT((Raw_Fuel_Detail!$A$3:$A$44=$A15)*(Raw_Fuel_Detail!$B$3:$B$44="Motor Car")*(Raw_Fuel_Detail!$C$1:$AL$1=H$4)*Raw_Fuel_Detail!$C$3:$AL$44) -> 1294 | I15: =SUM(B15:H15) -> 2505444 | J15: =IF($I15=0,0,B15/$I15) -> 0.00022910111 | K15: =IF($I15=0,0,C15/$I15) -> 8.3817479e-06 | L15: =IF($I15=0,0,D15/$I15) -> 0.44917109 | M15: =IF($I15=0,0,E15/$I15) -> 0.47021686 | N15: =IF($I15=0,0,F15/$I15) -> 0.064302774
A16: FY15-16 | B16: =SUMPRODUCT((Raw_Fuel_Detail!$A$3:$A$44=$A16)*(Raw_Fuel_Detail!$B$3:$B$44="Motor Car")*(Raw_Fuel_Detail!$C$1:$AL$1=B$4)*Raw_Fuel_Detail!$C$3:$AL$44) -> 689 | C16: =SUMPRODUCT((Raw_Fuel_Detail!$A$3:$A$44=$A16)*(Raw_Fuel_Detail!$B$3:$B$44="Motor Car")*(Raw_Fuel_Detail!$C$1:$AL$1=C$4)*Raw_Fuel_Detail!$C$3:$AL$44) -> 1904 | D16: =SUMPRODUCT((Raw_Fuel_Detail!$A$3:$A$44=$A16)*(Raw_Fuel_Detail!$B$3:$B$44="Motor Car")*(Raw_Fuel_Detail!$C$1:$AL$1=D$4)*Raw_Fuel_Detail!$C$3:$AL$44) -> 1291125 | E16: =SUMPRODUCT((Raw_Fuel_Detail!$A$3:$A$44=$A16)*(Raw_Fuel_Detail!$B$3:$B$44="Motor Car")*(Raw_Fuel_Detail!$C$1:$AL$1=E$4)*Raw_Fuel_Detail!$C$3:$AL$44) -> 1113663 | F16: =SUMPRODUCT((Raw_Fuel_Detail!$A$3:$A$44=$A16)*(Raw_Fuel_Detail!$B$3:$B$44="Motor Car")*(Raw_Fuel_Detail!$C$1:$AL$1=F$4)*Raw_Fuel_Detail!$C$3:$AL$44) -> 171639 | G16: =SUMPRODUCT((Raw_Fuel_Detail!$A$3:$A$44=$A16)*(Raw_Fuel_Detail!$B$3:$B$44="Motor Car")*(Raw_Fuel_Detail!$C$1:$AL$1=G$4)*Raw_Fuel_Detail!$C$3:$AL$44) -> 29029 | H16: =SUMPRODUCT((Raw_Fuel_Detail!$A$3:$A$44=$A16)*(Raw_Fuel_Detail!$B$3:$B$44="Motor Car")*(Raw_Fuel_Detail!$C$1:$AL$1=H$4)*Raw_Fuel_Detail!$C$3:$AL$44) -> 2998 | I16: =SUM(B16:H16) -> 2611047 | J16: =IF($I16=0,0,B16/$I16) -> 0.00026387882 | K16: =IF($I16=0,0,C16/$I16) -> 0.00072920939 | L16: =IF($I16=0,0,D16/$I16) -> 0.49448555 | M16: =IF($I16=0,0,E16/$I16) -> 0.42651971 | N16: =IF($I16=0,0,F16/$I16) -> 0.065735699
... A25: FY24-25 | B25: =SUMPRODUCT((Raw_Fuel_Detail!$A$3:$A$44=$A25)*(Raw_Fuel_Detail!$B$3:$B$44="Motor Car")*(Raw_Fuel_Detail!$C$1:$AL$1=B$4)*Raw_Fuel_Detail!$C$3:$AL$44) -> 107497 | C25: =SUMPRODUCT((Raw_Fuel_Detail!$A$3:$A$44=$A25)*(Raw_Fuel_Detail!$B$3:$B$44="Motor Car")*(Raw_Fuel_Detail!$C$1:$AL$1=C$4)*Raw_Fuel_Detail!$C$3:$AL$44) -> 348989 | D25: =SUMPRODUCT((Raw_Fuel_Detail!$A$3:$A$44=$A25)*(Raw_Fuel_Detail!$B$3:$B$44="Motor Car")*(Raw_Fuel_Detail!$C$1:$AL$1=D$4)*Raw_Fuel_Detail!$C$3:$AL$44) -> 2141947 | E25: =SUMPRODUCT((Raw_Fuel_Detail!$A$3:$A$44=$A25)*(Raw_Fuel_Detail!$B$3:$B$44="Motor Car")*(Raw_Fuel_Detail!$C$1:$AL$1=E$4)*Raw_Fuel_Detail!$C$3:$AL$44) -> 736112 | F25: =SUMPRODUCT((Raw_Fuel_Detail!$A$3:$A$44=$A25)*(Raw_Fuel_Detail!$B$3:$B$44="Motor Car")*(Raw_Fuel_Detail!$C$1:$AL$1=F$4)*Raw_Fuel_Detail!$C$3:$AL$44) -> 627297 | G25: =SUMPRODUCT((Raw_Fuel_Detail!$A$3:$A$44=$A25)*(Raw_Fuel_Detail!$B$3:$B$44="Motor Car")*(Raw_Fuel_Detail!$C$1:$AL$1=G$4)*Raw_Fuel_Detail!$C$3:$AL$44) -> 9612 | H25: =SUMPRODUCT((Raw_Fuel_Detail!$A$3:$A$44=$A25)*(Raw_Fuel_Detail!$B$3:$B$44="Motor Car")*(Raw_Fuel_Detail!$C$1:$AL$1=H$4)*Raw_Fuel_Detail!$C$3:$AL$44) -> 221 | I25: =SUM(B25:H25) -> 3971675 | J25: =IF($I25=0,0,B25/$I25) -> 0.02706591 | K25: =IF($I25=0,0,C25/$I25) -> 0.087869476 | L25: =IF($I25=0,0,D25/$I25) -> 0.53930571 | M25: =IF($I25=0,0,E25/$I25) -> 0.18534044 | N25: =IF($I25=0,0,F25/$I25) -> 0.15794268
A26: Total FY05–FY25 | B26: =SUM(B5:B25) -> 270341 | C26: =SUM(C5:C25) -> 1418709 | D26: =SUM(D5:D25) -> 28151225 | E26: =SUM(E5:E25) -> 16305108 | F26: =SUM(F5:F25) -> 4289617 | G26: =SUM(G5:G25) -> 900113 | H26: =SUM(H5:H25) -> 51720 | I26: =SUM(I5:I25) -> 51386833

Sheet Motor_Cab
A1: Motor Cab (taxi)
A2: Registrations (numbers) by fuel group. Formulas pull from Raw_Fuel_Detail using the fuel-group row.
A4: Financial Year | B4: EV | C4: Hybrid | D4: Petrol | E4: Diesel | F4: CNG | G4: LPG | H4: Other / NA | I4: Total | J4: EV % | K4: Hybrid % | L4: Petrol % | M4: Diesel % | N4: CNG %
A5: FY04-05 | B5: =SUMPRODUCT((Raw_Fuel_Detail!$A$3:$A$44=$A5)*(Raw_Fuel_Detail!$B$3:$B$44="Motor Cab")*(Raw_Fuel_Detail!$C$1:$AL$1=B$4)*Raw_Fuel_Detail!$C$3:$AL$44) -> 1 | C5: =SUMPRODUCT((Raw_Fuel_Detail!$A$3:$A$44=$A5)*(Raw_Fuel_Detail!$B$3:$B$44="Motor Cab")*(Raw_Fuel_Detail!$C$1:$AL$1=C$4)*Raw_Fuel_Detail!$C$3:$AL$44) -> 0 | D5: =SUMPRODUCT((Raw_Fuel_Detail!$A$3:$A$44=$A5)*(Raw_Fuel_Detail!$B$3:$B$44="Motor Cab")*(Raw_Fuel_Detail!$C$1:$AL$1=D$4)*Raw_Fuel_Detail!$C$3:$AL$44) -> 4913 | E5: =SUMPRODUCT((Raw_Fuel_Detail!$A$3:$A$44=$A5)*(Raw_Fuel_Detail!$B$3:$B$44="Motor Cab")*(Raw_Fuel_Detail!$C$1:$AL$1=E$4)*Raw_Fuel_Detail!$C$3:$AL$44) -> 24612 | F5: =SUMPRODUCT((Raw_Fuel_Detail!$A$3:$A$44=$A5)*(Raw_Fuel_Detail!$B$3:$B$44="Motor Cab")*(Raw_Fuel_Detail!$C$1:$AL$1=F$4)*Raw_Fuel_Detail!$C$3:$AL$44) -> 1094 | G5: =SUMPRODUCT((Raw_Fuel_Detail!$A$3:$A$44=$A5)*(Raw_Fuel_Detail!$B$3:$B$44="Motor Cab")*(Raw_Fuel_Detail!$C$1:$AL$1=G$4)*Raw_Fuel_Detail!$C$3:$AL$44) -> 1084 | H5: =SUMPRODUCT((Raw_Fuel_Detail!$A$3:$A$44=$A5)*(Raw_Fuel_Detail!$B$3:$B$44="Motor Cab")*(Raw_Fuel_Detail!$C$1:$AL$1=H$4)*Raw_Fuel_Detail!$C$3:$AL$44) -> 216 | I5: =SUM(B5:H5) -> 31920 | J5: =IF($I5=0,0,B5/$I5) -> 3.1328321e-05 | K5: =IF($I5=0,0,C5/$I5) -> 0 | L5: =IF($I5=0,0,D5/$I5) -> 0.15391604 | M5: =IF($I5=0,0,E5/$I5) -> 0.77105263 | N5: =IF($I5=0,0,F5/$I5) -> 0.034273183
A6: FY05-06 | B6: =SUMPRODUCT((Raw_Fuel_Detail!$A$3:$A$44=$A6)*(Raw_Fuel_Detail!$B$3:$B$44="Motor Cab")*(Raw_Fuel_Detail!$C$1:$AL$1=B$4)*Raw_Fuel_Detail!$C$3:$AL$44) -> 2 | C6: =SUMPRODUCT((Raw_Fuel_Detail!$A$3:$A$44=$A6)*(Raw_Fuel_Detail!$B$3:$B$44="Motor Cab")*(Raw_Fuel_Detail!$C$1:$AL$1=C$4)*Raw_Fuel_Detail!$C$3:$AL$44) -> 0 | D6: =SUMPRODUCT((Raw_Fuel_Detail!$A$3:$A$44=$A6)*(Raw_Fuel_Detail!$B$3:$B$44="Motor Cab")*(Raw_Fuel_Detail!$C$1:$AL$1=D$4)*Raw_Fuel_Detail!$C$3:$AL$44) -> 4619 | E6: =SUMPRODUCT((Raw_Fuel_Detail!$A$3:$A$44=$A6)*(Raw_Fuel_Detail!$B$3:$B$44="Motor Cab")*(Raw_Fuel_Detail!$C$1:$AL$1=E$4)*Raw_Fuel_Detail!$C$3:$AL$44) -> 32540 | F6: =SUMPRODUCT((Raw_Fuel_Detail!$A$3:$A$44=$A6)*(Raw_Fuel_Detail!$B$3:$B$44="Motor Cab")*(Raw_Fuel_Detail!$C$1:$AL$1=F$4)*Raw_Fuel_Detail!$C$3:$AL$44) -> 507 | G6: =SUMPRODUCT((Raw_Fuel_Detail!$A$3:$A$44=$A6)*(Raw_Fuel_Detail!$B$3:$B$44="Motor Cab")*(Raw_Fuel_Detail!$C$1:$AL$1=G$4)*Raw_Fuel_Detail!$C$3:$AL$44) -> 1589 | H6: =SUMPRODUCT((Raw_Fuel_Detail!$A$3:$A$44=$A6)*(Raw_Fuel_Detail!$B$3:$B$44="Motor Cab")*(Raw_Fuel_Detail!$C$1:$AL$1=H$4)*Raw_Fuel_Detail!$C$3:$AL$44) -> 225 | I6: =SUM(B6:H6) -> 39482 | J6: =IF($I6=0,0,B6/$I6) -> 5.0655995e-05 | K6: =IF($I6=0,0,C6/$I6) -> 0 | L6: =IF($I6=0,0,D6/$I6) -> 0.11699002 | M6: =IF($I6=0,0,E6/$I6) -> 0.82417304 | N6: =IF($I6=0,0,F6/$I6) -> 0.012841295
A7: FY06-07 | B7: =SUMPRODUCT((Raw_Fuel_Detail!$A$3:$A$44=$A7)*(Raw_Fuel_Detail!$B$3:$B$44="Motor Cab")*(Raw_Fuel_Detail!$C$1:$AL$1=B$4)*Raw_Fuel_Detail!$C$3:$AL$44) -> 3 | C7: =SUMPRODUCT((Raw_Fuel_Detail!$A$3:$A$44=$A7)*(Raw_Fuel_Detail!$B$3:$B$44="Motor Cab")*(Raw_Fuel_Detail!$C$1:$AL$1=C$4)*Raw_Fuel_Detail!$C$3:$AL$44) -> 1 | D7: =SUMPRODUCT((Raw_Fuel_Detail!$A$3:$A$44=$A7)*(Raw_Fuel_Detail!$B$3:$B$44="Motor Cab")*(Raw_Fuel_Detail!$C$1:$AL$1=D$4)*Raw_Fuel_Detail!$C$3:$AL$44) -> 5305 | E7: =SUMPRODUCT((Raw_Fuel_Detail!$A$3:$A$44=$A7)*(Raw_Fuel_Detail!$B$3:$B$44="Motor Cab")*(Raw_Fuel_Detail!$C$1:$AL$1=E$4)*Raw_Fuel_Detail!$C$3:$AL$44) -> 42110 | F7: =SUMPRODUCT((Raw_Fuel_Detail!$A$3:$A$44=$A7)*(Raw_Fuel_Detail!$B$3:$B$44="Motor Cab")*(Raw_Fuel_Detail!$C$1:$AL$1=F$4)*Raw_Fuel_Detail!$C$3:$AL$44) -> 1444 | G7: =SUMPRODUCT((Raw_Fuel_Detail!$A$3:$A$44=$A7)*(Raw_Fuel_Detail!$B$3:$B$44="Motor Cab")*(Raw_Fuel_Detail!$C$1:$AL$1=G$4)*Raw_Fuel_Detail!$C$3:$AL$44) -> 2428 | H7: =SUMPRODUCT((Raw_Fuel_Detail!$A$3:$A$44=$A7)*(Raw_Fuel_Detail!$B$3:$B$44="Motor Cab")*(Raw_Fuel_Detail!$C$1:$AL$1=H$4)*Raw_Fuel_Detail!$C$3:$AL$44) -> 324 | I7: =SUM(B7:H7) -> 51615 | J7: =IF($I7=0,0,B7/$I7) -> 5.8122639e-05 | K7: =IF($I7=0,0,C7/$I7) -> 1.9374213e-05 | L7: =IF($I7=0,0,D7/$I7) -> 0.1027802 | M7: =IF($I7=0,0,E7/$I7) -> 0.81584811 | N7: =IF($I7=0,0,F7/$I7) -> 0.027976363
A8: FY07-08 | B8: =SUMPRODUCT((Raw_Fuel_Detail!$A$3:$A$44=$A8)*(Raw_Fuel_Detail!$B$3:$B$44="Motor Cab")*(Raw_Fuel_Detail!$C$1:$AL$1=B$4)*Raw_Fuel_Detail!$C$3:$AL$44) -> 5 | C8: =SUMPRODUCT((Raw_Fuel_Detail!$A$3:$A$44=$A8)*(Raw_Fuel_Detail!$B$3:$B$44="Motor Cab")*(Raw_Fuel_Detail!$C$1:$AL$1=C$4)*Raw_Fuel_Detail!$C$3:$AL$44) -> 0 | D8: =SUMPRODUCT((Raw_Fuel_Detail!$A$3:$A$44=$A8)*(Raw_Fuel_Detail!$B$3:$B$44="Motor Cab")*(Raw_Fuel_Detail!$C$1:$AL$1=D$4)*Raw_Fuel_Detail!$C$3:$AL$44) -> 5120 | E8: =SUMPRODUCT((Raw_Fuel_Detail!$A$3:$A$44=$A8)*(Raw_Fuel_Detail!$B$3:$B$44="Motor Cab")*(Raw_Fuel_Detail!$C$1:$AL$1=E$4)*Raw_Fuel_Detail!$C$3:$AL$44) -> 48922 | F8: =SUMPRODUCT((Raw_Fuel_Detail!$A$3:$A$44=$A8)*(Raw_Fuel_Detail!$B$3:$B$44="Motor Cab")*(Raw_Fuel_Detail!$C$1:$AL$1=F$4)*Raw_Fuel_Detail!$C$3:$AL$44) -> 3159 | G8: =SUMPRODUCT((Raw_Fuel_Detail!$A$3:$A$44=$A8)*(Raw_Fuel_Detail!$B$3:$B$44="Motor Cab")*(Raw_Fuel_Detail!$C$1:$AL$1=G$4)*Raw_Fuel_Detail!$C$3:$AL$44) -> 2341 | H8: =SUMPRODUCT((Raw_Fuel_Detail!$A$3:$A$44=$A8)*(Raw_Fuel_Detail!$B$3:$B$44="Motor Cab")*(Raw_Fuel_Detail!$C$1:$AL$1=H$4)*Raw_Fuel_Detail!$C$3:$AL$44) -> 322 | I8: =SUM(B8:H8) -> 59869 | J8: =IF($I8=0,0,B8/$I8) -> 8.3515676e-05 | K8: =IF($I8=0,0,C8/$I8) -> 0 | L8: =IF($I8=0,0,D8/$I8) -> 0.085520052 | M8: =IF($I8=0,0,E8/$I8) -> 0.81715078 | N8: =IF($I8=0,0,F8/$I8) -> 0.052765204
A9: FY08-09 | B9: =SUMPRODUCT((Raw_Fuel_Detail!$A$3:$A$44=$A9)*(Raw_Fuel_Detail!$B$3:$B$44="Motor Cab")*(Raw_Fuel_Detail!$C$1:$AL$1=B$4)*Raw_Fuel_Detail!$C$3:$AL$44) -> 4 | C9: =SUMPRODUCT((Raw_Fuel_Detail!$A$3:$A$44=$A9)*(Raw_Fuel_Detail!$B$3:$B$44="Motor Cab")*(Raw_Fuel_Detail!$C$1:$AL$1=C$4)*Raw_Fuel_Detail!$C$3:$AL$44) -> 0 | D9: =SUMPRODUCT((Raw_Fuel_Detail!$A$3:$A$44=$A9)*(Raw_Fuel_Detail!$B$3:$B$44="Motor Cab")*(Raw_Fuel_Detail!$C$1:$AL$1=D$4)*Raw_Fuel_Detail!$C$3:$AL$44) -> 3539 | E9: =SUMPRODUCT((Raw_Fuel_Detail!$A$3:$A$44=$A9)*(Raw_Fuel_Detail!$B$3:$B$44="Motor Cab")*(Raw_Fuel_Detail!$C$1:$AL$1=E$4)*Raw_Fuel_Detail!$C$3:$AL$44) -> 49474 | F9: =SUMPRODUCT((Raw_Fuel_Detail!$A$3:$A$44=$A9)*(Raw_Fuel_Detail!$B$3:$B$44="Motor Cab")*(Raw_Fuel_Detail!$C$1:$AL$1=F$4)*Raw_Fuel_Detail!$C$3:$AL$44) -> 3793 | G9: =SUMPRODUCT((Raw_Fuel_Detail!$A$3:$A$44=$A9)*(Raw_Fuel_Detail!$B$3:$B$44="Motor Cab")*(Raw_Fuel_Detail!$C$1:$AL$1=G$4)*Raw_Fuel_Detail!$C$3:$AL$44) -> 1383 | H9: =SUMPRODUCT((Raw_Fuel_Detail!$A$3:$A$44=$A9)*(Raw_Fuel_Detail!$B$3:$B$44="Motor Cab")*(Raw_Fuel_Detail!$C$1:$AL$1=H$4)*Raw_Fuel_Detail!$C$3:$AL$44) -> 368 | I9: =SUM(B9:H9) -> 58561 | J9: =IF($I9=0,0,B9/$I9) -> 6.8304845e-05 | K9: =IF($I9=0,0,C9/$I9) -> 0 | L9: =IF($I9=0,0,D9/$I9) -> 0.060432711 | M9: =IF($I9=0,0,E9/$I9) -> 0.84482847 | N9: =IF($I9=0,0,F9/$I9) -> 0.064770069
A10: FY09-10 | B10: =SUMPRODUCT((Raw_Fuel_Detail!$A$3:$A$44=$A10)*(Raw_Fuel_Detail!$B$3:$B$44="Motor Cab")*(Raw_Fuel_Detail!$C$1:$AL$1=B$4)*Raw_Fuel_Detail!$C$3:$AL$44) -> 5 | C10: =SUMPRODUCT((Raw_Fuel_Detail!$A$3:$A$44=$A10)*(Raw_Fuel_Detail!$B$3:$B$44="Motor Cab")*(Raw_Fuel_Detail!$C$1:$AL$1=C$4)*Raw_Fuel_Detail!$C$3:$AL$44) -> 1 | D10: =SUMPRODUCT((Raw_Fuel_Detail!$A$3:$A$44=$A10)*(Raw_Fuel_Detail!$B$3:$B$44="Motor Cab")*(Raw_Fuel_Detail!$C$1:$AL$1=D$4)*Raw_Fuel_Detail!$C$3:$AL$44) -> 4224 | E10: =SUMPRODUCT((Raw_Fuel_Detail!$A$3:$A$44=$A10)*(Raw_Fuel_Detail!$B$3:$B$44="Motor Cab")*(Raw_Fuel_Detail!$C$1:$AL$1=E$4)*Raw_Fuel_Detail!$C$3:$AL$44) -> 64400 | F10: =SUMPRODUCT((Raw_Fuel_Detail!$A$3:$A$44=$A10)*(Raw_Fuel_Detail!$B$3:$B$44="Motor Cab")*(Raw_Fuel_Detail!$C$1:$AL$1=F$4)*Raw_Fuel_Detail!$C$3:$AL$44) -> 7329 | G10: =SUMPRODUCT((Raw_Fuel_Detail!$A$3:$A$44=$A10)*(Raw_Fuel_Detail!$B$3:$B$44="Motor Cab")*(Raw_Fuel_Detail!$C$1:$AL$1=G$4)*Raw_Fuel_Detail!$C$3:$AL$44) -> 1480 | H10: =SUMPRODUCT((Raw_Fuel_Detail!$A$3:$A$44=$A10)*(Raw_Fuel_Detail!$B$3:$B$44="Motor Cab")*(Raw_Fuel_Detail!$C$1:$AL$1=H$4)*Raw_Fuel_Detail!$C$3:$AL$44) -> 311 | I10: =SUM(B10:H10) -> 77750 | J10: =IF($I10=0,0,B10/$I10) -> 6.4308682e-05 | K10: =IF($I10=0,0,C10/$I10) -> 1.2861736e-05 | L10: =IF($I10=0,0,D10/$I10) -> 0.054327974 | M10: =IF($I10=0,0,E10/$I10) -> 0.82829582 | N10: =IF($I10=0,0,F10/$I10) -> 0.094263666
A11: FY10-11 | B11: =SUMPRODUCT((Raw_Fuel_Detail!$A$3:$A$44=$A11)*(Raw_Fuel_Detail!$B$3:$B$44="Motor Cab")*(Raw_Fuel_Detail!$C$1:$AL$1=B$4)*Raw_Fuel_Detail!$C$3:$AL$44) -> 16 | C11: =SUMPRODUCT((Raw_Fuel_Detail!$A$3:$A$44=$A11)*(Raw_Fuel_Detail!$B$3:$B$44="Motor Cab")*(Raw_Fuel_Detail!$C$1:$AL$1=C$4)*Raw_Fuel_Detail!$C$3:$AL$44) -> 1 | D11: =SUMPRODUCT((Raw_Fuel_Detail!$A$3:$A$44=$A11)*(Raw_Fuel_Detail!$B$3:$B$44="Motor Cab")*(Raw_Fuel_Detail!$C$1:$AL$1=D$4)*Raw_Fuel_Detail!$C$3:$AL$44) -> 6485 | E11: =SUMPRODUCT((Raw_Fuel_Detail!$A$3:$A$44=$A11)*(Raw_Fuel_Detail!$B$3:$B$44="Motor Cab")*(Raw_Fuel_Detail!$C$1:$AL$1=E$4)*Raw_Fuel_Detail!$C$3:$AL$44) -> 79253 | F11: =SUMPRODUCT((Raw_Fuel_Detail!$A$3:$A$44=$A11)*(Raw_Fuel_Detail!$B$3:$B$44="Motor Cab")*(Raw_Fuel_Detail!$C$1:$AL$1=F$4)*Raw_Fuel_Detail!$C$3:$AL$44) -> 17599 | G11: =SUMPRODUCT((Raw_Fuel_Detail!$A$3:$A$44=$A11)*(Raw_Fuel_Detail!$B$3:$B$44="Motor Cab")*(Raw_Fuel_Detail!$C$1:$AL$1=G$4)*Raw_Fuel_Detail!$C$3:$AL$44) -> 1562 | H11: =SUMPRODUCT((Raw_Fuel_Detail!$A$3:$A$44=$A11)*(Raw_Fuel_Detail!$B$3:$B$44="Motor Cab")*(Raw_Fuel_Detail!$C$1:$AL$1=H$4)*Raw_Fuel_Detail!$C$3:$AL$44) -> 79 | I11: =SUM(B11:H11) -> 104995 | J11: =IF($I11=0,0,B11/$I11) -> 0.00015238821 | K11: =IF($I11=0,0,C11/$I11) -> 9.5242631e-06 | L11: =IF($I11=0,0,D11/$I11) -> 0.061764846 | M11: =IF($I11=0,0,E11/$I11) -> 0.75482642 | N11: =IF($I11=0,0,F11/$I11) -> 0.16761751
A12: FY11-12 | B12: =SUMPRODUCT((Raw_Fuel_Detail!$A$3:$A$44=$A12)*(Raw_Fuel_Detail!$B$3:$B$44="Motor Cab")*(Raw_Fuel_Detail!$C$1:$AL$1=B$4)*Raw_Fuel_Detail!$C$3:$AL$44) -> 9 | C12: =SUMPRODUCT((Raw_Fuel_Detail!$A$3:$A$44=$A12)*(Raw_Fuel_Detail!$B$3:$B$44="Motor Cab")*(Raw_Fuel_Detail!$C$1:$AL$1=C$4)*Raw_Fuel_Detail!$C$3:$AL$44) -> 1 | D12: =SUMPRODUCT((Raw_Fuel_Detail!$A$3:$A$44=$A12)*(Raw_Fuel_Detail!$B$3:$B$44="Motor Cab")*(Raw_Fuel_Detail!$C$1:$AL$1=D$4)*Raw_Fuel_Detail!$C$3:$AL$44) -> 6215 | E12: =SUMPRODUCT((Raw_Fuel_Detail!$A$3:$A$44=$A12)*(Raw_Fuel_Detail!$B$3:$B$44="Motor Cab")*(Raw_Fuel_Detail!$C$1:$AL$1=E$4)*Raw_Fuel_Detail!$C$3:$AL$44) -> 95611 | F12: =SUMPRODUCT((Raw_Fuel_Detail!$A$3:$A$44=$A12)*(Raw_Fuel_Detail!$B$3:$B$44="Motor Cab")*(Raw_Fuel_Detail!$C$1:$AL$1=F$4)*Raw_Fuel_Detail!$C$3:$AL$44) -> 11392 | G12: =SUMPRODUCT((Raw_Fuel_Detail!$A$3:$A$44=$A12)*(Raw_Fuel_Detail!$B$3:$B$44="Motor Cab")*(Raw_Fuel_Detail!$C$1:$AL$1=G$4)*Raw_Fuel_Detail!$C$3:$AL$44) -> 1212 | H12: =SUMPRODUCT((Raw_Fuel_Detail!$A$3:$A$44=$A12)*(Raw_Fuel_Detail!$B$3:$B$44="Motor Cab")*(Raw_Fuel_Detail!$C$1:$AL$1=H$4)*Raw_Fuel_Detail!$C$3:$AL$44) -> 84 | I12: =SUM(B12:H12) -> 114524 | J12: =IF($I12=0,0,B12/$I12) -> 7.8586148e-05 | K12: =IF($I12=0,0,C12/$I12) -> 8.7317942e-06 | L12: =IF($I12=0,0,D12/$I12) -> 0.054268101 | M12: =IF($I12=0,0,E12/$I12) -> 0.83485558 | N12: =IF($I12=0,0,F12/$I12) -> 0.0994726
A13: FY12-13 | B13: =SUMPRODUCT((Raw_Fuel_Detail!$A$3:$A$44=$A13)*(Raw_Fuel_Detail!$B$3:$B$44="Motor Cab")*(Raw_Fuel_Detail!$C$1:$AL$1=B$4)*Raw_Fuel_Detail!$C$3:$AL$44) -> 8 | C13: =SUMPRODUCT((Raw_Fuel_Detail!$A$3:$A$44=$A13)*(Raw_Fuel_Detail!$B$3:$B$44="Motor Cab")*(Raw_Fuel_Detail!$C$1:$AL$1=C$4)*Raw_Fuel_Detail!$C$3:$AL$44) -> 3 | D13: =SUMPRODUCT((Raw_Fuel_Detail!$A$3:$A$44=$A13)*(Raw_Fuel_Detail!$B$3:$B$44="Motor Cab")*(Raw_Fuel_Detail!$C$1:$AL$1=D$4)*Raw_Fuel_Detail!$C$3:$AL$44) -> 5577 | E13: =SUMPRODUCT((Raw_Fuel_Detail!$A$3:$A$44=$A13)*(Raw_Fuel_Detail!$B$3:$B$44="Motor Cab")*(Raw_Fuel_Detail!$C$1:$AL$1=E$4)*Raw_Fuel_Detail!$C$3:$AL$44) -> 116455 | F13: =SUMPRODUCT((Raw_Fuel_Detail!$A$3:$A$44=$A13)*(Raw_Fuel_Detail!$B$3:$B$44="Motor Cab")*(Raw_Fuel_Detail!$C$1:$AL$1=F$4)*Raw_Fuel_Detail!$C$3:$AL$44) -> 7683 | G13: =SUMPRODUCT((Raw_Fuel_Detail!$A$3:$A$44=$A13)*(Raw_Fuel_Detail!$B$3:$B$44="Motor Cab")*(Raw_Fuel_Detail!$C$1:$AL$1=G$4)*Raw_Fuel_Detail!$C$3:$AL$44) -> 565 | H13: =SUMPRODUCT((Raw_Fuel_Detail!$A$3:$A$44=$A13)*(Raw_Fuel_Detail!$B$3:$B$44="Motor Cab")*(Raw_Fuel_Detail!$C$1:$AL$1=H$4)*Raw_Fuel_Detail!$C$3:$AL$44) -> 91 | I13: =SUM(B13:H13) -> 130382 | J13: =IF($I13=0,0,B13/$I13) -> 6.1358163e-05 | K13: =IF($I13=0,0,C13/$I13) -> 2.3009311e-05 | L13: =IF($I13=0,0,D13/$I13) -> 0.042774309 | M13: =IF($I13=0,0,E13/$I13) -> 0.89318311 | N13: =IF($I13=0,0,F13/$I13) -> 0.058926846
A14: FY13-14 | B14: =SUMPRODUCT((Raw_Fuel_Detail!$A$3:$A$44=$A14)*(Raw_Fuel_Detail!$B$3:$B$44="Motor Cab")*(Raw_Fuel_Detail!$C$1:$AL$1=B$4)*Raw_Fuel_Detail!$C$3:$AL$44) -> 23 | C14: =SUMPRODUCT((Raw_Fuel_Detail!$A$3:$A$44=$A14)*(Raw_Fuel_Detail!$B$3:$B$44="Motor Cab")*(Raw_Fuel_Detail!$C$1:$AL$1=C$4)*Raw_Fuel_Detail!$C$3:$AL$44) -> 0 | D14: =SUMPRODUCT((Raw_Fuel_Detail!$A$3:$A$44=$A14)*(Raw_Fuel_Detail!$B$3:$B$44="Motor Cab")*(Raw_Fuel_Detail!$C$1:$AL$1=D$4)*Raw_Fuel_Detail!$C$3:$AL$44) -> 6173 | E14: =SUMPRODUCT((Raw_Fuel_Detail!$A$3:$A$44=$A14)*(Raw_Fuel_Detail!$B$3:$B$44="Motor Cab")*(Raw_Fuel_Detail!$C$1:$AL$1=E$4)*Raw_Fuel_Detail!$C$3:$AL$44) -> 102413 | F14: =SUMPRODUCT((Raw_Fuel_Detail!$A$3:$A$44=$A14)*(Raw_Fuel_Detail!$B$3:$B$44="Motor Cab")*(Raw_Fuel_Detail!$C$1:$AL$1=F$4)*Raw_Fuel_Detail!$C$3:$AL$44) -> 9329 | G14: =SUMPRODUCT((Raw_Fuel_Detail!$A$3:$A$44=$A14)*(Raw_Fuel_Detail!$B$3:$B$44="Motor Cab")*(Raw_Fuel_Detail!$C$1:$AL$1=G$4)*Raw_Fuel_Detail!$C$3:$AL$44) -> 374 | H14: =SUMPRODUCT((Raw_Fuel_Detail!$A$3:$A$44=$A14)*(Raw_Fuel_Detail!$B$3:$B$44="Motor Cab")*(Raw_Fuel_Detail!$C$1:$AL$1=H$4)*Raw_Fuel_Detail!$C$3:$AL$44) -> 91 | I14: =SUM(B14:H14) -> 118403 | J14: =IF($I14=0,0,B14/$I14) -> 0.00019425183 | K14: =IF($I14=0,0,C14/$I14) -> 0 | L14: =IF($I14=0,0,D14/$I14) -> 0.052135503 | M14: =IF($I14=0,0,E14/$I14) -> 0.86495275 | N14: =IF($I14=0,0,F14/$I14) -> 0.078790233
A15: FY14-15 | B15: =SUMPRODUCT((Raw_Fuel_Detail!$A$3:$A$44=$A15)*(Raw_Fuel_Detail!$B$3:$B$44="Motor Cab")*(Raw_Fuel_Detail!$C$1:$AL$1=B$4)*Raw_Fuel_Detail!$C$3:$AL$44) -> 6 | C15: =SUMPRODUCT((Raw_Fuel_Detail!$A$3:$A$44=$A15)*(Raw_Fuel_Detail!$B$3:$B$44="Motor Cab")*(Raw_Fuel_Detail!$C$1:$AL$1=C$4)*Raw_Fuel_Detail!$C$3:$AL$44) -> 2 | D15: =SUMPRODUCT((Raw_Fuel_Detail!$A$3:$A$44=$A15)*(Raw_Fuel_Detail!$B$3:$B$44="Motor Cab")*(Raw_Fuel_Detail!$C$1:$AL$1=D$4)*Raw_Fuel_Detail!$C$3:$AL$44) -> 6593 | E15: =SUMPRODUCT((Raw_Fuel_Detail!$A$3:$A$44=$A15)*(Raw_Fuel_Detail!$B$3:$B$44="Motor Cab")*(Raw_Fuel_Detail!$C$1:$AL$1=E$4)*Raw_Fuel_Detail!$C$3:$AL$44) -> 85001 | F15: =SUMPRODUCT((Raw_Fuel_Detail!$A$3:$A$44=$A15)*(Raw_Fuel_Detail!$B$3:$B$44="Motor Cab")*(Raw_Fuel_Detail!$C$1:$AL$1=F$4)*Raw_Fuel_Detail!$C$3:$AL$44) -> 9618 | G15: =SUMPRODUCT((Raw_Fuel_Detail!$A$3:$A$44=$A15)*(Raw_Fuel_Detail!$B$3:$B$44="Motor Cab")*(Raw_Fuel_Detail!$C$1:$AL$1=G$4)*Raw_Fuel_Detail!$C$3:$AL$44) -> 450 | H15: =SUMPRODUCT((Raw_Fuel_Detail!$A$3:$A$44=$A15)*(Raw_Fuel_Detail!$B$3:$B$44="Motor Cab")*(Raw_Fuel_Detail!$C$1:$AL$1=H$4)*Raw_Fuel_Detail!$C$3:$AL$44) -> 82 | I15: =SUM(B15:H15) -> 101752 | J15: =IF($I15=0,0,B15/$I15) -> 5.89669e-05 | K15: =IF($I15=0,0,C15/$I15) -> 1.9655633e-05 | L15: =IF($I15=0,0,D15/$I15) -> 0.064794795 | M15: =IF($I15=0,0,E15/$I15) -> 0.83537424 | N15: =IF($I15=0,0,F15/$I15) -> 0.094523941
A16: FY15-16 | B16: =SUMPRODUCT((Raw_Fuel_Detail!$A$3:$A$44=$A16)*(Raw_Fuel_Detail!$B$3:$B$44="Motor Cab")*(Raw_Fuel_Detail!$C$1:$AL$1=B$4)*Raw_Fuel_Detail!$C$3:$AL$44) -> 115 | C16: =SUMPRODUCT((Raw_Fuel_Detail!$A$3:$A$44=$A16)*(Raw_Fuel_Detail!$B$3:$B$44="Motor Cab")*(Raw_Fuel_Detail!$C$1:$AL$1=C$4)*Raw_Fuel_Detail!$C$3:$AL$44) -> 71 | D16: =SUMPRODUCT((Raw_Fuel_Detail!$A$3:$A$44=$A16)*(Raw_Fuel_Detail!$B$3:$B$44="Motor Cab")*(Raw_Fuel_Detail!$C$1:$AL$1=D$4)*Raw_Fuel_Detail!$C$3:$AL$44) -> 8923 | E16: =SUMPRODUCT((Raw_Fuel_Detail!$A$3:$A$44=$A16)*(Raw_Fuel_Detail!$B$3:$B$44="Motor Cab")*(Raw_Fuel_Detail!$C$1:$AL$1=E$4)*Raw_Fuel_Detail!$C$3:$AL$44) -> 111742 | F16: =SUMPRODUCT((Raw_Fuel_Detail!$A$3:$A$44=$A16)*(Raw_Fuel_Detail!$B$3:$B$44="Motor Cab")*(Raw_Fuel_Detail!$C$1:$AL$1=F$4)*Raw_Fuel_Detail!$C$3:$AL$44) -> 19920 | G16: =SUMPRODUCT((Raw_Fuel_Detail!$A$3:$A$44=$A16)*(Raw_Fuel_Detail!$B$3:$B$44="Motor Cab")*(Raw_Fuel_Detail!$C$1:$AL$1=G$4)*Raw_Fuel_Detail!$C$3:$AL$44) -> 537 | H16: =SUMPRODUCT((Raw_Fuel_Detail!$A$3:$A$44=$A16)*(Raw_Fuel_Detail!$B$3:$B$44="Motor Cab")*(Raw_Fuel_Detail!$C$1:$AL$1=H$4)*Raw_Fuel_Detail!$C$3:$AL$44) -> 196 | I16: =SUM(B16:H16) -> 141504 | J16: =IF($I16=0,0,B16/$I16) -> 0.00081269787 | K16: =IF($I16=0,0,C16/$I16) -> 0.0005017526 | L16: =IF($I16=0,0,D16/$I16) -> 0.063058288 | M16: =IF($I16=0,0,E16/$I16) -> 0.78967379 | N16: =IF($I16=0,0,F16/$I16) -> 0.14077341
... A25: FY24-25 | B25: =SUMPRODUCT((Raw_Fuel_Detail!$A$3:$A$44=$A25)*(Raw_Fuel_Detail!$B$3:$B$44="Motor Cab")*(Raw_Fuel_Detail!$C$1:$AL$1=B$4)*Raw_Fuel_Detail!$C$3:$AL$44) -> 8426 | C25: =SUMPRODUCT((Raw_Fuel_Detail!$A$3:$A$44=$A25)*(Raw_Fuel_Detail!$B$3:$B$44="Motor Cab")*(Raw_Fuel_Detail!$C$1:$AL$1=C$4)*Raw_Fuel_Detail!$C$3:$AL$44) -> 12685 | D25: =SUMPRODUCT((Raw_Fuel_Detail!$A$3:$A$44=$A25)*(Raw_Fuel_Detail!$B$3:$B$44="Motor Cab")*(Raw_Fuel_Detail!$C$1:$AL$1=D$4)*Raw_Fuel_Detail!$C$3:$AL$44) -> 51088 | E25: =SUMPRODUCT((Raw_Fuel_Detail!$A$3:$A$44=$A25)*(Raw_Fuel_Detail!$B$3:$B$44="Motor Cab")*(Raw_Fuel_Detail!$C$1:$AL$1=E$4)*Raw_Fuel_Detail!$C$3:$AL$44) -> 31953 | F25: =SUMPRODUCT((Raw_Fuel_Detail!$A$3:$A$44=$A25)*(Raw_Fuel_Detail!$B$3:$B$44="Motor Cab")*(Raw_Fuel_Detail!$C$1:$AL$1=F$4)*Raw_Fuel_Detail!$C$3:$AL$44) -> 200311 | G25: =SUMPRODUCT((Raw_Fuel_Detail!$A$3:$A$44=$A25)*(Raw_Fuel_Detail!$B$3:$B$44="Motor Cab")*(Raw_Fuel_Detail!$C$1:$AL$1=G$4)*Raw_Fuel_Detail!$C$3:$AL$44) -> 374 | H25: =SUMPRODUCT((Raw_Fuel_Detail!$A$3:$A$44=$A25)*(Raw_Fuel_Detail!$B$3:$B$44="Motor Cab")*(Raw_Fuel_Detail!$C$1:$AL$1=H$4)*Raw_Fuel_Detail!$C$3:$AL$44) -> 98 | I25: =SUM(B25:H25) -> 304935 | J25: =IF($I25=0,0,B25/$I25) -> 0.027632118 | K25: =IF($I25=0,0,C25/$I25) -> 0.041599029 | L25: =IF($I25=0,0,D25/$I25) -> 0.16753734 | M25: =IF($I25=0,0,E25/$I25) -> 0.10478627 | N25: =IF($I25=0,0,F25/$I25) -> 0.65689737
A26: Total FY05–FY25 | B26: =SUM(B5:B25) -> 31392 | C26: =SUM(C5:C25) -> 31340 | D26: =SUM(D5:D25) -> 311410 | E26: =SUM(E5:E25) -> 1337928 | F26: =SUM(F5:F25) -> 714323 | G26: =SUM(G5:G25) -> 20803 | H26: =SUM(H5:H25) -> 3850 | I26: =SUM(I5:I25) -> 2451046

Sheet Car_plus_Cab
A1: Motor Car + Motor Cab
A2: Registrations (numbers) by fuel group. Formulas pull from Raw_Fuel_Detail using the fuel-group row.
A4: Financial Year | B4: EV | C4: Hybrid | D4: Petrol | E4: Diesel | F4: CNG | G4: LPG | H4: Other / NA | I4: Total | J4: EV % | K4: Hybrid % | L4: Petrol % | M4: Diesel % | N4: CNG %
A5: FY04-05 | B5: =SUMPRODUCT((Raw_Fuel_Detail!$A$3:$A$44=$A5)*(Raw_Fuel_Detail!$C$1:$AL$1=B$4)*Raw_Fuel_Detail!$C$3:$AL$44) -> 204 | C5: =SUMPRODUCT((Raw_Fuel_Detail!$A$3:$A$44=$A5)*(Raw_Fuel_Detail!$C$1:$AL$1=C$4)*Raw_Fuel_Detail!$C$3:$AL$44) -> 23 | D5: =SUMPRODUCT((Raw_Fuel_Detail!$A$3:$A$44=$A5)*(Raw_Fuel_Detail!$C$1:$AL$1=D$4)*Raw_Fuel_Detail!$C$3:$AL$44) -> 548460 | E5: =SUMPRODUCT((Raw_Fuel_Detail!$A$3:$A$44=$A5)*(Raw_Fuel_Detail!$C$1:$AL$1=E$4)*Raw_Fuel_Detail!$C$3:$AL$44) -> 272388 | F5: =SUMPRODUCT((Raw_Fuel_Detail!$A$3:$A$44=$A5)*(Raw_Fuel_Detail!$C$1:$AL$1=F$4)*Raw_Fuel_Detail!$C$3:$AL$44) -> 55977 | G5: =SUMPRODUCT((Raw_Fuel_Detail!$A$3:$A$44=$A5)*(Raw_Fuel_Detail!$C$1:$AL$1=G$4)*Raw_Fuel_Detail!$C$3:$AL$44) -> 48942 | H5: =SUMPRODUCT((Raw_Fuel_Detail!$A$3:$A$44=$A5)*(Raw_Fuel_Detail!$C$1:$AL$1=H$4)*Raw_Fuel_Detail!$C$3:$AL$44) -> 2106 | I5: =SUM(B5:H5) -> 928100 | J5: =IF($I5=0,0,B5/$I5) -> 0.0002198039 | K5: =IF($I5=0,0,C5/$I5) -> 2.4781812e-05 | L5: =IF($I5=0,0,D5/$I5) -> 0.59094925 | M5: =IF($I5=0,0,E5/$I5) -> 0.29348993 | N5: =IF($I5=0,0,F5/$I5) -> 0.060313544
A6: FY05-06 | B6: =SUMPRODUCT((Raw_Fuel_Detail!$A$3:$A$44=$A6)*(Raw_Fuel_Detail!$C$1:$AL$1=B$4)*Raw_Fuel_Detail!$C$3:$AL$44) -> 182 | C6: =SUMPRODUCT((Raw_Fuel_Detail!$A$3:$A$44=$A6)*(Raw_Fuel_Detail!$C$1:$AL$1=C$4)*Raw_Fuel_Detail!$C$3:$AL$44) -> 19 | D6: =SUMPRODUCT((Raw_Fuel_Detail!$A$3:$A$44=$A6)*(Raw_Fuel_Detail!$C$1:$AL$1=D$4)*Raw_Fuel_Detail!$C$3:$AL$44) -> 611219 | E6: =SUMPRODUCT((Raw_Fuel_Detail!$A$3:$A$44=$A6)*(Raw_Fuel_Detail!$C$1:$AL$1=E$4)*Raw_Fuel_Detail!$C$3:$AL$44) -> 311668 | F6: =SUMPRODUCT((Raw_Fuel_Detail!$A$3:$A$44=$A6)*(Raw_Fuel_Detail!$C$1:$AL$1=F$4)*Raw_Fuel_Detail!$C$3:$AL$44) -> 71001 | G6: =SUMPRODUCT((Raw_Fuel_Detail!$A$3:$A$44=$A6)*(Raw_Fuel_Detail!$C$1:$AL$1=G$4)*Raw_Fuel_Detail!$C$3:$AL$44) -> 50809 | H6: =SUMPRODUCT((Raw_Fuel_Detail!$A$3:$A$44=$A6)*(Raw_Fuel_Detail!$C$1:$AL$1=H$4)*Raw_Fuel_Detail!$C$3:$AL$44) -> 2163 | I6: =SUM(B6:H6) -> 1047061 | J6: =IF($I6=0,0,B6/$I6) -> 0.00017381986 | K6: =IF($I6=0,0,C6/$I6) -> 1.814603e-05 | L6: =IF($I6=0,0,D6/$I6) -> 0.58374727 | M6: =IF($I6=0,0,E6/$I6) -> 0.29765983 | N6: =IF($I6=0,0,F6/$I6) -> 0.067809803
A7: FY06-07 | B7: =SUMPRODUCT((Raw_Fuel_Detail!$A$3:$A$44=$A7)*(Raw_Fuel_Detail!$C$1:$AL$1=B$4)*Raw_Fuel_Detail!$C$3:$AL$44) -> 246 | C7: =SUMPRODUCT((Raw_Fuel_Detail!$A$3:$A$44=$A7)*(Raw_Fuel_Detail!$C$1:$AL$1=C$4)*Raw_Fuel_Detail!$C$3:$AL$44) -> 25 | D7: =SUMPRODUCT((Raw_Fuel_Detail!$A$3:$A$44=$A7)*(Raw_Fuel_Detail!$C$1:$AL$1=D$4)*Raw_Fuel_Detail!$C$3:$AL$44) -> 716733 | E7: =SUMPRODUCT((Raw_Fuel_Detail!$A$3:$A$44=$A7)*(Raw_Fuel_Detail!$C$1:$AL$1=E$4)*Raw_Fuel_Detail!$C$3:$AL$44) -> 374700 | F7: =SUMPRODUCT((Raw_Fuel_Detail!$A$3:$A$44=$A7)*(Raw_Fuel_Detail!$C$1:$AL$1=F$4)*Raw_Fuel_Detail!$C$3:$AL$44) -> 88630 | G7: =SUMPRODUCT((Raw_Fuel_Detail!$A$3:$A$44=$A7)*(Raw_Fuel_Detail!$C$1:$AL$1=G$4)*Raw_Fuel_Detail!$C$3:$AL$44) -> 73913 | H7: =SUMPRODUCT((Raw_Fuel_Detail!$A$3:$A$44=$A7)*(Raw_Fuel_Detail!$C$1:$AL$1=H$4)*Raw_Fuel_Detail!$C$3:$AL$44) -> 3525 | I7: =SUM(B7:H7) -> 1257772 | J7: =IF($I7=0,0,B7/$I7) -> 0.00019558394 | K7: =IF($I7=0,0,C7/$I7) -> 1.9876416e-05 | L7: =IF($I7=0,0,D7/$I7) -> 0.56984334 | M7: =IF($I7=0,0,E7/$I7) -> 0.29790773 | N7: =IF($I7=0,0,F7/$I7) -> 0.070465871
A8: FY07-08 | B8: =SUMPRODUCT((Raw_Fuel_Detail!$A$3:$A$44=$A8)*(Raw_Fuel_Detail!$C$1:$AL$1=B$4)*Raw_Fuel_Detail!$C$3:$AL$44) -> 341 | C8: =SUMPRODUCT((Raw_Fuel_Detail!$A$3:$A$44=$A8)*(Raw_Fuel_Detail!$C$1:$AL$1=C$4)*Raw_Fuel_Detail!$C$3:$AL$44) -> 20 | D8: =SUMPRODUCT((Raw_Fuel_Detail!$A$3:$A$44=$A8)*(Raw_Fuel_Detail!$C$1:$AL$1=D$4)*Raw_Fuel_Detail!$C$3:$AL$44) -> 786708 | E8: =SUMPRODUCT((Raw_Fuel_Detail!$A$3:$A$44=$A8)*(Raw_Fuel_Detail!$C$1:$AL$1=E$4)*Raw_Fuel_Detail!$C$3:$AL$44) -> 466799 | F8: =SUMPRODUCT((Raw_Fuel_Detail!$A$3:$A$44=$A8)*(Raw_Fuel_Detail!$C$1:$AL$1=F$4)*Raw_Fuel_Detail!$C$3:$AL$44) -> 106273 | G8: =SUMPRODUCT((Raw_Fuel_Detail!$A$3:$A$44=$A8)*(Raw_Fuel_Detail!$C$1:$AL$1=G$4)*Raw_Fuel_Detail!$C$3:$AL$44) -> 85388 | H8: =SUMPRODUCT((Raw_Fuel_Detail!$A$3:$A$44=$A8)*(Raw_Fuel_Detail!$C$1:$AL$1=H$4)*Raw_Fuel_Detail!$C$3:$AL$44) -> 3152 | I8: =SUM(B8:H8) -> 1448681 | J8: =IF($I8=0,0,B8/$I8) -> 0.00023538653 | K8: =IF($I8=0,0,C8/$I8) -> 1.3805662e-05 | L8: =IF($I8=0,0,D8/$I8) -> 0.54305123 | M8: =IF($I8=0,0,E8/$I8) -> 0.32222346 | N8: =IF($I8=0,0,F8/$I8) -> 0.073358455
A9: FY08-09 | B9: =SUMPRODUCT((Raw_Fuel_Detail!$A$3:$A$44=$A9)*(Raw_Fuel_Detail!$C$1:$AL$1=B$4)*Raw_Fuel_Detail!$C$3:$AL$44) -> 494 | C9: =SUMPRODUCT((Raw_Fuel_Detail!$A$3:$A$44=$A9)*(Raw_Fuel_Detail!$C$1:$AL$1=C$4)*Raw_Fuel_Detail!$C$3:$AL$44) -> 22 | D9: =SUMPRODUCT((Raw_Fuel_Detail!$A$3:$A$44=$A9)*(Raw_Fuel_Detail!$C$1:$AL$1=D$4)*Raw_Fuel_Detail!$C$3:$AL$44) -> 791224 | E9: =SUMPRODUCT((Raw_Fuel_Detail!$A$3:$A$44=$A9)*(Raw_Fuel_Detail!$C$1:$AL$1=E$4)*Raw_Fuel_Detail!$C$3:$AL$44) -> 534668 | F9: =SUMPRODUCT((Raw_Fuel_Detail!$A$3:$A$44=$A9)*(Raw_Fuel_Detail!$C$1:$AL$1=F$4)*Raw_Fuel_Detail!$C$3:$AL$44) -> 105130 | G9: =SUMPRODUCT((Raw_Fuel_Detail!$A$3:$A$44=$A9)*(Raw_Fuel_Detail!$C$1:$AL$1=G$4)*Raw_Fuel_Detail!$C$3:$AL$44) -> 83157 | H9: =SUMPRODUCT((Raw_Fuel_Detail!$A$3:$A$44=$A9)*(Raw_Fuel_Detail!$C$1:$AL$1=H$4)*Raw_Fuel_Detail!$C$3:$AL$44) -> 2744 | I9: =SUM(B9:H9) -> 1517439 | J9: =IF($I9=0,0,B9/$I9) -> 0.00032554851 | K9: =IF($I9=0,0,C9/$I9) -> 1.4498112e-05 | L9: =IF($I9=0,0,D9/$I9) -> 0.52142063 | M9: =IF($I9=0,0,E9/$I9) -> 0.35234892 | N9: =IF($I9=0,0,F9/$I9) -> 0.069281203
A10: FY09-10 | B10: =SUMPRODUCT((Raw_Fuel_Detail!$A$3:$A$44=$A10)*(Raw_Fuel_Detail!$C$1:$AL$1=B$4)*Raw_Fuel_Detail!$C$3:$AL$44) -> 272 | C10: =SUMPRODUCT((Raw_Fuel_Detail!$A$3:$A$44=$A10)*(Raw_Fuel_Detail!$C$1:$AL$1=C$4)*Raw_Fuel_Detail!$C$3:$AL$44) -> 38 | D10: =SUMPRODUCT((Raw_Fuel_Detail!$A$3:$A$44=$A10)*(Raw_Fuel_Detail!$C$1:$AL$1=D$4)*Raw_Fuel_Detail!$C$3:$AL$44) -> 981717 | E10: =SUMPRODUCT((Raw_Fuel_Detail!$A$3:$A$44=$A10)*(Raw_Fuel_Detail!$C$1:$AL$1=E$4)*Raw_Fuel_Detail!$C$3:$AL$44) -> 672890 | F10: =SUMPRODUCT((Raw_Fuel_Detail!$A$3:$A$44=$A10)*(Raw_Fuel_Detail!$C$1:$AL$1=F$4)*Raw_Fuel_Detail!$C$3:$AL$44) -> 130581 | G10: =SUMPRODUCT((Raw_Fuel_Detail!$A$3:$A$44=$A10)*(Raw_Fuel_Detail!$C$1:$AL$1=G$4)*Raw_Fuel_Detail!$C$3:$AL$44) -> 96083 | H10: =SUMPRODUCT((Raw_Fuel_Detail!$A$3:$A$44=$A10)*(Raw_Fuel_Detail!$C$1:$AL$1=H$4)*Raw_Fuel_Detail!$C$3:$AL$44) -> 2782 | I10: =SUM(B10:H10) -> 1884363 | J10: =IF($I10=0,0,B10/$I10) -> 0.00014434586 | K10: =IF($I10=0,0,C10/$I10) -> 2.0165966e-05 | L10: =IF($I10=0,0,D10/$I10) -> 0.52098083 | M10: =IF($I10=0,0,E10/$I10) -> 0.35709149 | N10: =IF($I10=0,0,F10/$I10) -> 0.069297158
A11: FY10-11 | B11: =SUMPRODUCT((Raw_Fuel_Detail!$A$3:$A$44=$A11)*(Raw_Fuel_Detail!$C$1:$AL$1=B$4)*Raw_Fuel_Detail!$C$3:$AL$44) -> 387 | C11: =SUMPRODUCT((Raw_Fuel_Detail!$A$3:$A$44=$A11)*(Raw_Fuel_Detail!$C$1:$AL$1=C$4)*Raw_Fuel_Detail!$C$3:$AL$44) -> 27 | D11: =SUMPRODUCT((Raw_Fuel_Detail!$A$3:$A$44=$A11)*(Raw_Fuel_Detail!$C$1:$AL$1=D$4)*Raw_Fuel_Detail!$C$3:$AL$44) -> 1204650 | E11: =SUMPRODUCT((Raw_Fuel_Detail!$A$3:$A$44=$A11)*(Raw_Fuel_Detail!$C$1:$AL$1=E$4)*Raw_Fuel_Detail!$C$3:$AL$44) -> 847935 | F11: =SUMPRODUCT((Raw_Fuel_Detail!$A$3:$A$44=$A11)*(Raw_Fuel_Detail!$C$1:$AL$1=F$4)*Raw_Fuel_Detail!$C$3:$AL$44) -> 186365 | G11: =SUMPRODUCT((Raw_Fuel_Detail!$A$3:$A$44=$A11)*(Raw_Fuel_Detail!$C$1:$AL$1=G$4)*Raw_Fuel_Detail!$C$3:$AL$44) -> 83722 | H11: =SUMPRODUCT((Raw_Fuel_Detail!$A$3:$A$44=$A11)*(Raw_Fuel_Detail!$C$1:$AL$1=H$4)*Raw_Fuel_Detail!$C$3:$AL$44) -> 2733 | I11: =SUM(B11:H11) -> 2325819 | J11: =IF($I11=0,0,B11/$I11) -> 0.000166393 | K11: =IF($I11=0,0,C11/$I11) -> 1.1608814e-05 | L11: =IF($I11=0,0,D11/$I11) -> 0.51794658 | M11: =IF($I11=0,0,E11/$I11) -> 0.3645748 | N11: =IF($I11=0,0,F11/$I11) -> 0.080128763
A12: FY11-12 | B12: =SUMPRODUCT((Raw_Fuel_Detail!$A$3:$A$44=$A12)*(Raw_Fuel_Detail!$C$1:$AL$1=B$4)*Raw_Fuel_Detail!$C$3:$AL$44) -> 685 | C12: =SUMPRODUCT((Raw_Fuel_Detail!$A$3:$A$44=$A12)*(Raw_Fuel_Detail!$C$1:$AL$1=C$4)*Raw_Fuel_Detail!$C$3:$AL$44) -> 22 | D12: =SUMPRODUCT((Raw_Fuel_Detail!$A$3:$A$44=$A12)*(Raw_Fuel_Detail!$C$1:$AL$1=D$4)*Raw_Fuel_Detail!$C$3:$AL$44) -> 1118207 | E12: =SUMPRODUCT((Raw_Fuel_Detail!$A$3:$A$44=$A12)*(Raw_Fuel_Detail!$C$1:$AL$1=E$4)*Raw_Fuel_Detail!$C$3:$AL$44) -> 1144966 | F12: =SUMPRODUCT((Raw_Fuel_Detail!$A$3:$A$44=$A12)*(Raw_Fuel_Detail!$C$1:$AL$1=F$4)*Raw_Fuel_Detail!$C$3:$AL$44) -> 194309 | G12: =SUMPRODUCT((Raw_Fuel_Detail!$A$3:$A$44=$A12)*(Raw_Fuel_Detail!$C$1:$AL$1=G$4)*Raw_Fuel_Detail!$C$3:$AL$44) -> 85235 | H12: =SUMPRODUCT((Raw_Fuel_Detail!$A$3:$A$44=$A12)*(Raw_Fuel_Detail!$C$1:$AL$1=H$4)*Raw_Fuel_Detail!$C$3:$AL$44) -> 2794 | I12: =SUM(B12:H12) -> 2546218 | J12: =IF($I12=0,0,B12/$I12) -> 0.00026902645 | K12: =IF($I12=0,0,C12/$I12) -> 8.6402657e-06 | L12: =IF($I12=0,0,D12/$I12) -> 0.43916389 | M12: =IF($I12=0,0,E12/$I12) -> 0.4496732 | N12: =IF($I12=0,0,F12/$I12) -> 0.07631279
A13: FY12-13 | B13: =SUMPRODUCT((Raw_Fuel_Detail!$A$3:$A$44=$A13)*(Raw_Fuel_Detail!$C$1:$AL$1=B$4)*Raw_Fuel_Detail!$C$3:$AL$44) -> 216 | C13: =SUMPRODUCT((Raw_Fuel_Detail!$A$3:$A$44=$A13)*(Raw_Fuel_Detail!$C$1:$AL$1=C$4)*Raw_Fuel_Detail!$C$3:$AL$44) -> 41 | D13: =SUMPRODUCT((Raw_Fuel_Detail!$A$3:$A$44=$A13)*(Raw_Fuel_Detail!$C$1:$AL$1=D$4)*Raw_Fuel_Detail!$C$3:$AL$44) -> 940914 | E13: =SUMPRODUCT((Raw_Fuel_Detail!$A$3:$A$44=$A13)*(Raw_Fuel_Detail!$C$1:$AL$1=E$4)*Raw_Fuel_Detail!$C$3:$AL$44) -> 1427189 | F13: =SUMPRODUCT((Raw_Fuel_Detail!$A$3:$A$44=$A13)*(Raw_Fuel_Detail!$C$1:$AL$1=F$4)*Raw_Fuel_Detail!$C$3:$AL$44) -> 158068 | G13: =SUMPRODUCT((Raw_Fuel_Detail!$A$3:$A$44=$A13)*(Raw_Fuel_Detail!$C$1:$AL$1=G$4)*Raw_Fuel_Detail!$C$3:$AL$44) -> 64540 | H13: =SUMPRODUCT((Raw_Fuel_Detail!$A$3:$A$44=$A13)*(Raw_Fuel_Detail!$C$1:$AL$1=H$4)*Raw_Fuel_Detail!$C$3:$AL$44) -> 2521 | I13: =SUM(B13:H13) -> 2593489 | J13: =IF($I13=0,0,B13/$I13) -> 8.3285489e-05 | K13: =IF($I13=0,0,C13/$I13) -> 1.580882e-05 | L13: =IF($I13=0,0,D13/$I13) -> 0.36279853 | M13: =IF($I13=0,0,E13/$I13) -> 0.55029692 | N13: =IF($I13=0,0,F13/$I13) -> 0.060948013
A14: FY13-14 | B14: =SUMPRODUCT((Raw_Fuel_Detail!$A$3:$A$44=$A14)*(Raw_Fuel_Detail!$C$1:$AL$1=B$4)*Raw_Fuel_Detail!$C$3:$AL$44) -> 447 | C14: =SUMPRODUCT((Raw_Fuel_Detail!$A$3:$A$44=$A14)*(Raw_Fuel_Detail!$C$1:$AL$1=C$4)*Raw_Fuel_Detail!$C$3:$AL$44) -> 23 | D14: =SUMPRODUCT((Raw_Fuel_Detail!$A$3:$A$44=$A14)*(Raw_Fuel_Detail!$C$1:$AL$1=D$4)*Raw_Fuel_Detail!$C$3:$AL$44) -> 965291 | E14: =SUMPRODUCT((Raw_Fuel_Detail!$A$3:$A$44=$A14)*(Raw_Fuel_Detail!$C$1:$AL$1=E$4)*Raw_Fuel_Detail!$C$3:$AL$44) -> 1313977 | F14: =SUMPRODUCT((Raw_Fuel_Detail!$A$3:$A$44=$A14)*(Raw_Fuel_Detail!$C$1:$AL$1=F$4)*Raw_Fuel_Detail!$C$3:$AL$44) -> 143753 | G14: =SUMPRODUCT((Raw_Fuel_Detail!$A$3:$A$44=$A14)*(Raw_Fuel_Detail!$C$1:$AL$1=G$4)*Raw_Fuel_Detail!$C$3:$AL$44) -> 37397 | H14: =SUMPRODUCT((Raw_Fuel_Detail!$A$3:$A$44=$A14)*(Raw_Fuel_Detail!$C$1:$AL$1=H$4)*Raw_Fuel_Detail!$C$3:$AL$44) -> 1920 | I14: =SUM(B14:H14) -> 2462808 | J14: =IF($I14=0,0,B14/$I14) -> 0.00018150014 | K14: =IF($I14=0,0,C14/$I14) -> 9.3389334e-06 | L14: =IF($I14=0,0,D14/$I14) -> 0.39194732 | M14: =IF($I14=0,0,E14/$I14) -> 0.53352799 | N14: =IF($I14=0,0,F14/$I14) -> 0.058369552
A15: FY14-15 | B15: =SUMPRODUCT((Raw_Fuel_Detail!$A$3:$A$44=$A15)*(Raw_Fuel_Detail!$C$1:$AL$1=B$4)*Raw_Fuel_Detail!$C$3:$AL$44) -> 580 | C15: =SUMPRODUCT((Raw_Fuel_Detail!$A$3:$A$44=$A15)*(Raw_Fuel_Detail!$C$1:$AL$1=C$4)*Raw_Fuel_Detail!$C$3:$AL$44) -> 23 | D15: =SUMPRODUCT((Raw_Fuel_Detail!$A$3:$A$44=$A15)*(Raw_Fuel_Detail!$C$1:$AL$1=D$4)*Raw_Fuel_Detail!$C$3:$AL$44) -> 1131966 | E15: =SUMPRODUCT((Raw_Fuel_Detail!$A$3:$A$44=$A15)*(Raw_Fuel_Detail!$C$1:$AL$1=E$4)*Raw_Fuel_Detail!$C$3:$AL$44) -> 1263103 | F15: =SUMPRODUCT((Raw_Fuel_Detail!$A$3:$A$44=$A15)*(Raw_Fuel_Detail!$C$1:$AL$1=F$4)*Raw_Fuel_Detail!$C$3:$AL$44) -> 170725 | G15: =SUMPRODUCT((Raw_Fuel_Detail!$A$3:$A$44=$A15)*(Raw_Fuel_Detail!$C$1:$AL$1=G$4)*Raw_Fuel_Detail!$C$3:$AL$44) -> 39423 | H15: =SUMPRODUCT((Raw_Fuel_Detail!$A$3:$A$44=$A15)*(Raw_Fuel_Detail!$C$1:$AL$1=H$4)*Raw_Fuel_Detail!$C$3:$AL$44) -> 1376 | I15: =SUM(B15:H15) -> 2607196 | J15: =IF($I15=0,0,B15/$I15) -> 0.00022246122 | K15: =IF($I15=0,0,C15/$I15) -> 8.821738e-06 | L15: =IF($I15=0,0,D15/$I15) -> 0.43416989 | M15: =IF($I15=0,0,E15/$I15) -> 0.48446799 | N15: =IF($I15=0,0,F15/$I15) -> 0.065482227
A16: FY15-16 | B16: =SUMPRODUCT((Raw_Fuel_Detail!$A$3:$A$44=$A16)*(Raw_Fuel_Detail!$C$1:$AL$1=B$4)*Raw_Fuel_Detail!$C$3:$AL$44) -> 804 | C16: =SUMPRODUCT((Raw_Fuel_Detail!$A$3:$A$44=$A16)*(Raw_Fuel_Detail!$C$1:$AL$1=C$4)*Raw_Fuel_Detail!$C$3:$AL$44) -> 1975 | D16: =SUMPRODUCT((Raw_Fuel_Detail!$A$3:$A$44=$A16)*(Raw_Fuel_Detail!$C$1:$AL$1=D$4)*Raw_Fuel_Detail!$C$3:$AL$44) -> 1300048 | E16: =SUMPRODUCT((Raw_Fuel_Detail!$A$3:$A$44=$A16)*(Raw_Fuel_Detail!$C$1:$AL$1=E$4)*Raw_Fuel_Detail!$C$3:$AL$44) -> 1225405 | F16: =SUMPRODUCT((Raw_Fuel_Detail!$A$3:$A$44=$A16)*(Raw_Fuel_Detail!$C$1:$AL$1=F$4)*Raw_Fuel_Detail!$C$3:$AL$44) -> 191559 | G16: =SUMPRODUCT((Raw_Fuel_Detail!$A$3:$A$44=$A16)*(Raw_Fuel_Detail!$C$1:$AL$1=G$4)*Raw_Fuel_Detail!$C$3:$AL$44) -> 29566 | H16: =SUMPRODUCT((Raw_Fuel_Detail!$A$3:$A$44=$A16)*(Raw_Fuel_Detail!$C$1:$AL$1=H$4)*Raw_Fuel_Detail!$C$3:$AL$44) -> 3194 | I16: =SUM(B16:H16) -> 2752551 | J16: =IF($I16=0,0,B16/$I16) -> 0.00029209268 | K16: =IF($I16=0,0,C16/$I16) -> 0.00071751622 | L16: =IF($I16=0,0,D16/$I16) -> 0.4723066 | M16: =IF($I16=0,0,E16/$I16) -> 0.44518884 | N16: =IF($I16=0,0,F16/$I16) -> 0.069593261
... A25: FY24-25 | B25: =SUMPRODUCT((Raw_Fuel_Detail!$A$3:$A$44=$A25)*(Raw_Fuel_Detail!$C$1:$AL$1=B$4)*Raw_Fuel_Detail!$C$3:$AL$44) -> 115923 | C25: =SUMPRODUCT((Raw_Fuel_Detail!$A$3:$A$44=$A25)*(Raw_Fuel_Detail!$C$1:$AL$1=C$4)*Raw_Fuel_Detail!$C$3:$AL$44) -> 361674 | D25: =SUMPRODUCT((Raw_Fuel_Detail!$A$3:$A$44=$A25)*(Raw_Fuel_Detail!$C$1:$AL$1=D$4)*Raw_Fuel_Detail!$C$3:$AL$44) -> 2193035 | E25: =SUMPRODUCT((Raw_Fuel_Detail!$A$3:$A$44=$A25)*(Raw_Fuel_Detail!$C$1:$AL$1=E$4)*Raw_Fuel_Detail!$C$3:$AL$44) -> 768065 | F25: =SUMPRODUCT((Raw_Fuel_Detail!$A$3:$A$44=$A25)*(Raw_Fuel_Detail!$C$1:$AL$1=F$4)*Raw_Fuel_Detail!$C$3:$AL$44) -> 827608 | G25: =SUMPRODUCT((Raw_Fuel_Detail!$A$3:$A$44=$A25)*(Raw_Fuel_Detail!$C$1:$AL$1=G$4)*Raw_Fuel_Detail!$C$3:$AL$44) -> 9986 | H25: =SUMPRODUCT((Raw_Fuel_Detail!$A$3:$A$44=$A25)*(Raw_Fuel_Detail!$C$1:$AL$1=H$4)*Raw_Fuel_Detail!$C$3:$AL$44) -> 319 | I25: =SUM(B25:H25) -> 4276610 | J25: =IF($I25=0,0,B25/$I25) -> 0.027106283 | K25: =IF($I25=0,0,C25/$I25) -> 0.084570255 | L25: =IF($I25=0,0,D25/$I25) -> 0.51279752 | M25: =IF($I25=0,0,E25/$I25) -> 0.17959669 | N25: =IF($I25=0,0,F25/$I25) -> 0.19351963
A26: Total FY05–FY25 | B26: =SUM(B5:B25) -> 301733 | C26: =SUM(C5:C25) -> 1450049 | D26: =SUM(D5:D25) -> 28462635 | E26: =SUM(E5:E25) -> 17643036 | F26: =SUM(F5:F25) -> 5003940 | G26: =SUM(G5:G25) -> 920916 | H26: =SUM(H5:H25) -> 55570 | I26: =SUM(I5:I25) -> 53837879

Sheet Raw_Fuel_Detail
A1: Fuel group → | C1: CNG | D1: Diesel | E1: CNG | F1: CNG | G1: Diesel | H1: Hybrid | I1: Diesel | J1: CNG | K1: CNG | L1: CNG | M1: EV | N1: Petrol | O1: Diesel | P1: Petrol | Q1: EV | R1: CNG | S1: Other / NA | T1: CNG | U1: LPG | V1: Petrol | W1: Other / NA | X1: Petrol | Y1: CNG | Z1: Petrol | AA1: CNG | AB1: Hybrid | AC1: Hybrid | AD1: LPG | AE1: Hybrid | AF1: Hybrid | AG1: LPG | AH1: Petrol | AI1: Hybrid | AJ1: EV | AK1: EV | AL1: Hybrid
A2: Financial Year | B2: Vehicle Class | C2: BIO-CNG/BIO-GAS | D2: BIO-DIESEL(B100) | E2: BIO-METHANE | F2: CNG ONLY | G2: DIESEL | H2: DIESEL/HYBRID | I2: DI-METHYL ETHER | J2: DUAL DIESEL/BIO CNG | K2: DUAL DIESEL/CNG | L2: DUAL DIESEL/LNG | M2: ELECTRIC(BOV) | N2: ETHANOL(E100) | O2: FLEX-FUEL(BIO-DIESEL) | P2: FLEX-FUEL(ETHANOL) | Q2: FUEL CELL HYDROGEN | R2: HCNG | S2: HYDROGEN(ICE) | T2: LNG | U2: LPG ONLY | V2: METHANOL | W2: NOT APPLICABLE | X2: PETROL | Y2: PETROL/CNG | Z2: PETROL(E20) | AA2: PETROL(E20)/CNG | AB2: PETROL(E20)/HYBRID | AC2: PETROL(E20)/HYBRID/CNG | AD2: PETROL(E20)/LPG | AE2: PETROL/HYBRID | AF2: PETROL/HYBRID/CNG | AG2: PETROL/LPG | AH2: PETROL/METHANOL | AI2: PLUG-IN HYBRID EV | AJ2: PURE EV | AK2: SOLAR | AL2: STRONG HYBRID EV | AM2: Vahan TOTAL | AN2: Check (sum − total)
A3: FY04-05 | B3: Motor Car | C3: 1 | D3: 0 | E3: 0 | F3: 907 | G3: 247776 | H3: 15 | I3: 0 | J3: 0 | K3: 0 | L3: 0 | M3: 195 | N3: 0 | O3: 0 | P3: 0 | Q3: 0 | R3: 0 | S3: 0 | T3: 0 | U3: 852 | V3: 1 | W3: 1890 | X3: 543546 | Y3: 53975 | Z3: 0 | AA3: 0 | AB3: 0 | AC3: 0 | AD3: 1 | AE3: 8 | AF3: 0 | AG3: 47005 | AH3: 0 | AI3: 0 | AJ3: 0 | AK3: 8 | AL3: 0 | AM3: 896180 | AN3: =SUM(C3:AL3)-AM3 -> 0
A4: FY04-05 | B4: Motor Cab | C4: 0 | D4: 0 | E4: 0 | F4: 162 | G4: 24612 | H4: 0 | I4: 0 | J4: 0 | K4: 0 | L4: 0 | M4: 1 | N4: 0 | O4: 0 | P4: 0 | Q4: 0 | R4: 0 | S4: 0 | T4: 0 | U4: 61 | V4: 0 | W4: 216 | X4: 4913 | Y4: 932 | Z4: 0 | AA4: 0 | AB4: 0 | AC4: 0 | AD4: 0 | AE4: 0 | AF4: 0 | AG4: 1023 | AH4: 0 | AI4: 0 | AJ4: 0 | AK4: 0 | AL4: 0 | AM4: 31920 | AN4: =SUM(C4:AL4)-AM4 -> 0
A5: FY05-06 | B5: Motor Car | C5: 0 | D5: 0 | E5: 0 | F5: 877 | G5: 279128 | H5: 16 | I5: 0 | J5: 0 | K5: 0 | L5: 0 | M5: 170 | N5: 1 | O5: 0 | P5: 0 | Q5: 0 | R5: 0 | S5: 0 | T5: 1 | U5: 1011 | V5: 1 | W5: 1938 | X5: 606595 | Y5: 69616 | Z5: 3 | AA5: 0 | AB5: 0 | AC5: 0 | AD5: 0 | AE5: 3 | AF5: 0 | AG5: 48209 | AH5: 0 | AI5: 0 | AJ5: 0 | AK5: 10 | AL5: 0 | AM5: 1007579 | AN5: =SUM(C5:AL5)-AM5 -> 0
A6: FY05-06 | B6: Motor Cab | C6: 0 | D6: 0 | E6: 0 | F6: 131 | G6: 32540 | H6: 0 | I6: 0 | J6: 0 | K6: 0 | L6: 0 | M6: 0 | N6: 0 | O6: 0 | P6: 0 | Q6: 0 | R6: 0 | S6: 0 | T6: 0 | U6: 40 | V6: 0 | W6: 225 | X6: 4619 | Y6: 376 | Z6: 0 | AA6: 0 | AB6: 0 | AC6: 0 | AD6: 0 | AE6: 0 | AF6: 0 | AG6: 1549 | AH6: 0 | AI6: 0 | AJ6: 0 | AK6: 2 | AL6: 0 | AM6: 39482 | AN6: =SUM(C6:AL6)-AM6 -> 0
A7: FY06-07 | B7: Motor Car | C7: 0 | D7: 0 | E7: 0 | F7: 529 | G7: 332590 | H7: 21 | I7: 0 | J7: 0 | K7: 0 | L7: 0 | M7: 230 | N7: 0 | O7: 0 | P7: 0 | Q7: 0 | R7: 0 | S7: 0 | T7: 2 | U7: 2007 | V7: 0 | W7: 3201 | X7: 711417 | Y7: 86655 | Z7: 11 | AA7: 0 | AB7: 0 | AC7: 0 | AD7: 1 | AE7: 3 | AF7: 0 | AG7: 69477 | AH7: 0 | AI7: 0 | AJ7: 0 | AK7: 13 | AL7: 0 | AM7: 1206157 | AN7: =SUM(C7:AL7)-AM7 -> 0
A8: FY06-07 | B8: Motor Cab | C8: 0 | D8: 0 | E8: 0 | F8: 521 | G8: 42110 | H8: 1 | I8: 0 | J8: 0 | K8: 0 | L8: 0 | M8: 2 | N8: 0 | O8: 0 | P8: 0 | Q8: 0 | R8: 0 | S8: 0 | T8: 0 | U8: 55 | V8: 0 | W8: 324 | X8: 5305 | Y8: 923 | Z8: 0 | AA8: 0 | AB8: 0 | AC8: 0 | AD8: 0 | AE8: 0 | AF8: 0 | AG8: 2373 | AH8: 0 | AI8: 0 | AJ8: 0 | AK8: 1 | AL8: 0 | AM8: 51615 | AN8: =SUM(C8:AL8)-AM8 -> 0
A9: FY07-08 | B9: Motor Car | C9: 0 | D9: 0 | E9: 0 | F9: 260 | G9: 417876 | H9: 16 | I9: 1 | J9: 0 | K9: 0 | L9: 0 | M9: 326 | N9: 1 | O9: 0 | P9: 0 | Q9: 1 | R9: 0 | S9: 0 | T9: 0 | U9: 2228 | V9: 0 | W9: 2830 | X9: 781583 | Y9: 102853 | Z9: 4 | AA9: 1 | AB9: 0 | AC9: 0 | AD9: 1 | AE9: 4 | AF9: 0 | AG9: 80818 | AH9: 0 | AI9: 0 | AJ9: 0 | AK9: 9 | AL9: 0 | AM9: 1388812 | AN9: =SUM(C9:AL9)-AM9 -> 0
A10: FY07-08 | B10: Motor Cab | C10: 0 | D10: 0 | E10: 0 | F10: 1171 | G10: 48922 | H10: 0 | I10: 0 | J10: 0 | K10: 0 | L10: 0 | M10: 5 | N10: 0 | O10: 0 | P10: 0 | Q10: 0 | R10: 0 | S10: 0 | T10: 0 | U10: 58 | V10: 0 | W10: 322 | X10: 5120 | Y10: 1988 | Z10: 0 | AA10: 0 | AB10: 0 | AC10: 0 | AD10: 0 | AE10: 0 | AF10: 0 | AG10: 2283 | AH10: 0 | AI10: 0 | AJ10: 0 | AK10: 0 | AL10: 0 | AM10: 59869 | AN10: =SUM(C10:AL10)-AM10 -> 0
A11: FY08-09 | B11: Motor Car | C11: 0 | D11: 0 | E11: 0 | F11: 242 | G11: 485194 | H11: 18 | I11: 0 | J11: 0 | K11: 2 | L11: 0 | M11: 483 | N11: 0 | O11: 0 | P11: 0 | Q11: 0 | R11: 0 | S11: 0 | T11: 1 | U11: 1427 | V11: 1 | W11: 2376 | X11: 787678 | Y11: 101091 | Z11: 6 | AA11: 1 | AB11: 0 | AC11: 0 | AD11: 3 | AE11: 4 | AF11: 0 | AG11: 80344 | AH11: 0 | AI11: 0 | AJ11: 0 | AK11: 7 | AL11: 0 | AM11: 1458878 | AN11: =SUM(C11:AL11)-AM11 -> 0
A12: FY08-09 | B12: Motor Cab | C12: 0 | D12: 0 | E12: 0 | F12: 878 | G12: 49474 | H12: 0 | I12: 0 | J12: 0 | K12: 0 | L12: 0 | M12: 2 | N12: 0 | O12: 0 | P12: 0 | Q12: 0 | R12: 0 | S12: 0 | T12: 0 | U12: 48 | V12: 0 | W12: 368 | X12: 3539 | Y12: 2915 | Z12: 0 | AA12: 0 | AB12: 0 | AC12: 0 | AD12: 0 | AE12: 0 | AF12: 0 | AG12: 1335 | AH12: 0 | AI12: 0 | AJ12: 0 | AK12: 2 | AL12: 0 | AM12: 58561 | AN12: =SUM(C12:AL12)-AM12 -> 0
A13: FY09-10 | B13: Motor Car | C13: 0 | D13: 0 | E13: 0 | F13: 289 | G13: 608490 | H13: 28 | I13: 0 | J13: 0 | K13: 0 | L13: 0 | M13: 255 | N13: 0 | O13: 0 | P13: 0 | Q13: 1 | R13: 0 | S13: 0 | T13: 0 | U13: 676 | V13: 0 | W13: 2471 | X13: 977476 | Y13: 122962 | Z13: 17 | AA13: 1 | AB13: 0 | AC13: 0 | AD13: 11 | AE13: 9 | AF13: 0 | AG13: 93916 | AH13: 0 | AI13: 0 | AJ13: 0 | AK13: 11 | AL13: 0 | AM13: 1806613 | AN13: =SUM(C13:AL13)-AM13 -> 0
A14: FY09-10 | B14: Motor Cab | C14: 0 | D14: 0 | E14: 0 | F14: 843 | G14: 64400 | H14: 0 | I14: 0 | J14: 0 | K14: 0 | L14: 0 | M14: 5 | N14: 0 | O14: 0 | P14: 0 | Q14: 0 | R14: 0 | S14: 0 | T14: 0 | U14: 21 | V14: 0 | W14: 311 | X14: 4224 | Y14: 6486 | Z14: 0 | AA14: 0 | AB14: 0 | AC14: 0 | AD14: 0 | AE14: 1 | AF14: 0 | AG14: 1459 | AH14: 0 | AI14: 0 | AJ14: 0 | AK14: 0 | AL14: 0 | AM14: 77750 | AN14: =SUM(C14:AL14)-AM14 -> 0
... A44: FY24-25 | B44: Motor Cab | C44: 0 | D44: 0 | E44: 0 | F44: 125 | G44: 31953 | H44: 23 | I44: 0 | J44: 0 | K44: 0 | L44: 0 | M44: 4479 | N44: 0 | O44: 0 | P44: 0 | Q44: 0 | R44: 0 | S44: 0 | T44: 0 | U44: 0 | V44: 0 | W44: 98 | X44: 51014 | Y44: 200150 | Z44: 74 | AA44: 36 | AB44: 0 | AC44: 23 | AD44: 2 | AE44: 11016 | AF44: 155 | AG44: 372 | AH44: 0 | AI44: 0 | AJ44: 3947 | AK44: 0 | AL44: 1468 | AM44: 304935 | AN44: =SUM(C44:AL44)-AM44 -> 0
A46: Source: VAHAN Dashboard (vahan.parivahan.gov.in), Y-axis Vehicle Class × X-axis Fuel, Financial Year, All States, All RTOs, Actual values. Scraped 29-Oct-2026 using the logic of github.com/RevTpark/vahan-scraper (api.py).

Sheet Fuel_Mapping
A1: Fuel group | B1: Vahan fuel types included
A2: EV | B2: ELECTRIC(BOV), PURE EV, FUEL CELL HYDROGEN, SOLAR
